Workbook

Sheet 202304
B2: 预测机构 | C2: 更新日期 | D2: 供需 | E2: 2023Q1 | F2: 2023Q2 | G2: 2023Q2供需差 | H2: 2023Q3 | I2: 2023Q4
B3: IEA | C3: 4.14 | D3: 供 | E3: 101.3 | F3: 100.8 | G3: -0.4 | H3: 101.1 | I3: 101
D4: 需 | E4: 100.4 | F4: 101.2 | H4: 103.1 | I4: 103
C5: 3.14 | D5: 供 | E5: 101.2 | F5: 101.6 | G5: 0.3 | H5: 101.8 | I5: 101.7
D6: 需 | E6: 100.3 | F6: 101.3 | H6: 103 | I6: 103.5
B7: EIA | C7: 4.6 | D7: 供 | E7: 101.04 | F7: 101.12 | G7: 0.42 | H7: 101.49 | I7: 101.54
D8: 需 | E8: 100.01 | F8: 100.7 | H8: 101.36 | I8: 101.43
C9: 3.7 | D9: 供 | E9: 100.74 | F9: 101.29 | G9: 0.69 | H9: 101.91 | I9: 101.93
D10: 需 | E10: 99.97 | F10: 100.6 | H10: 101.47 | I10: 101.55
B11: IHS | C11: 4.17 | D11: 供 | E11: 103.73 | F11: 102 | G11: 0.96 | H11: 102.01 | I11: 103.18
D12: 需 | E12: 100.13 | F12: 101.04 | H12: 103.23 | I12: 103.06
C13: 3.17 | D13: 供 | E13: 103.17 | F13: 102.14 | G13: 1.35 | H13: 103.12 | I13: 103.41
D14: 需 | E14: 100.07 | F14: 100.79 | H14: 103 | I14: 102.91
B15: Woodmac | C15: 4.9 | D15: 供 | E15: 101.98 | F15: 101.23 | G15: 0.38 | H15: 102.08 | I15: 102.85
D16: 需 | E16: 99.74 | F16: 100.85 | H16: 103.02 | I16: 103.07
C17: 3.9 | D17: 供 | E17: 101.55 | F17: 101.7 | G17: 0.74 | H17: 102.61 | I17: 103.29
D18: 需 | E18: 99.97 | F18: 100.96 | H18: 103.11 | I18: 103.07
B19: Rystad | C19: 4.13 | D19: 供 | E19: 100.88 | F19: 100.56 | G19: -3.09 | H19: 101.14 | I19: 101.3
D20: 需 | E20: 101.59 | F20: 103.65 | H20: 103.65 | I20: 104.16
C21: 3.17 | D21: 供 | E21: 100.93 | F21: 101.53 | G21: -0.15 | H21: 102.56 | I21: 102.82
D22: 需 | E22: 101.32 | F22: 101.68 | H22: 103.77 | I22: 104.44

Sheet 202305
B2: 预测机构 | C2: 更新日期 | D2: 供需 | E2: 2023Q1 | F2: 2023Q2 | G2: 2023Q2供需差 | H2: 2023Q3 | I2: 2023Q4
B3: IEA | C3: 5.16 | D3: 供 | E3: 101.4 | F3: 100.6 | G3: -0.7 | H3: 101.1 | I3: 101.1
D4: 需 | E4: 100.5 | F4: 101.3 | H4: 103 | I4: 103.1
C5: 4.14 | D5: 供 | E5: 101.3 | F5: 100.8 | G5: -0.4 | H5: 101.1 | I5: 101
D6: 需 | E6: 100.4 | F6: 101.2 | H6: 103.1 | I6: 103
B7: EIA | C7: 5.4 | D7: 供 | E7: 100.96 | F7: 101.11 | G7: 0.29 | H7: 101.58 | I7: 101.71
D8: 需 | E8: 99.94 | F8: 100.82 | H8: 101.58 | I8: 101.67
C9: 4.6 | D9: 供 | E9: 101.04 | F9: 101.12 | G9: 0.42 | H9: 101.49 | I9: 101.54
D10: 需 | E10: 100.01 | F10: 100.7 | H10: 101.36 | I10: 101.43
B11: IHS | C11: 5.17 | D11: 供 | E11: 103.67 | F11: 102.1 | G11: 1 | H11: 102.27 | I11: 103.47
D12: 需 | E12: 101.12 | F12: 101.1 | H12: 103.42 | I12: 103.38
C13: 4.17 | D13: 供 | E13: 103.73 | F13: 102 | G13: 0.96 | H13: 102.01 | I13: 103.18
D14: 需 | E14: 100.13 | F14: 101.04 | H14: 103.23 | I14: 103.06
B15: Woodmac | C15: 5.9 | D15: 供 | E15: 102.06 | F15: 100.85 | G15: -0.1 | H15: 101.63 | I15: 102.45
D16: 需 | E16: 99.58 | F16: 100.95 | H16: 103.06 | I16: 103.11
C17: 4.9 | D17: 供 | E17: 101.98 | F17: 101.23 | G17: 0.38 | H17: 102.08 | I17: 102.85
D18: 需 | E18: 99.74 | F18: 100.85 | H18: 103.02 | I18: 103.07
B19: Rystad | C19: 5.17 | D19: 供 | E19: 101.01 | F19: 100.72 | G19: -0.87 | H19: 101.33 | I19: 101.55
D20: 需 | E20: 101.02 | F20: 101.59 | H20: 103.13 | I20: 103.48
C21: 4.13 | D21: 供 | E21: 100.88 | F21: 100.56 | G21: -3.09 | H21: 101.14 | I21: 101.3
D22: 需 | E22: 101.59 | F22: 103.65 | H22: 103.65 | I22: 104.16

Sheet 202306
B2: 预测机构 | C2: 更新日期 | D2: 供需 | E2: 2023Q1 | F2: 2023Q2 | G2: 2023Q3 | H2: 2023Q3供需差 | I2: 2023Q4
B3: IEA | C3: 6.14 | D3: 供 | E3: 101.4 | F3: 100.6 | G3: 101.2 | H3: -2.2 | I3: 101.1
D4: 需 | E4: 100.5 | F4: 101.3 | G4: 103.4 | I4: 103.1
C5: 5.16 | D5: 供 | E5: 101.3 | F5: 100.8 | G5: 101 | H5: 0.4 | I5: 101.1
D6: 需 | E6: 100.4 | F6: 101.2 | G6: 100.6 | I6: 103.1
B7: EIA | C7: 6.5 | D7: 供 | E7: 100.96 | F7: 101.11 | G7: 101.4 | H7: -0.2 | I7: 101.71
D8: 需 | E8: 99.94 | F8: 100.82 | G8: 101.6 | I8: 101.67
C9: 5.4 | D9: 供 | E9: 101.04 | F9: 101.12 | G9: 101.49 | H9: 0.13 | I9: 101.54
D10: 需 | E10: 100.01 | F10: 100.7 | G10: 101.36 | I10: 101.43
B11: IHS | C11: 6.2 | D11: 供 | E11: 103.67 | F11: 102.1 | G11: 102 | H11: -1.6 | I11: 103.53
D12: 需 | E12: 101.12 | F12: 101.1 | G12: 103.6 | I12: 103.6
C13: 5.17 | D13: 供 | E13: 103.73 | F13: 102 | G13: 102.01 | H13: -1.13 | I13: 103.18
D14: 需 | E14: 100.13 | F14: 101.04 | G14: 103.23 | I14: 103.06
B15: Woodmac | C15: 6.8 | D15: 供 | E15: 102.06 | F15: 100.85 | G15: 100.95 | H15: -1.89 | I15: 102.34
D16: 需 | E16: 99.58 | F16: 100.95 | G16: 102.84 | I16: 102.9
C17: 5.9 | D17: 供 | E17: 101.98 | F17: 101.23 | G17: 102.08 | H17: -0.94 | I17: 102.85
D18: 需 | E18: 99.74 | F18: 100.85 | G18: 103.02 | I18: 103.07
B19: Rystad | C19: 6.22 | D19: 供 | E19: 101.01 | F19: 100.72 | G19: 100.82 | H19: -2.64 | I19: 101.55
D20: 需 | E20: 101.02 | F20: 101.59 | G20: 103.46 | I20: 103.48
C21: 5.17 | D21: 供 | E21: 100.88 | F21: 100.56 | G21: 101.14 | H21: -2.51 | I21: 101.3
D22: 需 | E22: 101.59 | F22: 103.65 | G22: 103.65 | I22: 104.16

Sheet 202307
B2: 预测机构 | C2: 更新日期 | D2: 供需 | E2: 2023Q1 | F2: 2023Q2 | G2: 2023Q3 | H2: 2023Q3供需差 | I2: 2023Q4
B3: IEA | C3: 7.13 | D3: 供 | E3: 101.4 | F3: 100.6 | G3: 101.1 | H3: =G3-G4 -> -2 | I3: 101.1
D4: 需 | E4: 100.5 | F4: 101.3 | G4: 103.1 | I4: 103.1
C5: 6.14 | D5: 供 | E5: 101.4 | F5: 100.6 | G5: 101.2 | H5: -2.2 | I5: 101.1
D6: 需 | E6: 100.5 | F6: 101.3 | G6: 103.4 | I6: 103.1
B7: EIA | C7: 6.6 | D7: 供 | E7: 100.96 | F7: 101.11 | G7: 100.8 | H7: =G7-G8 -> -0.9 | I7: 101.71
D8: 需 | E8: 99.94 | F8: 100.82 | G8: 101.7 | I8: 101.67
C9: 6.5 | D9: 供 | E9: 100.96 | F9: 101.11 | G9: 101.4 | H9: -0.2 | I9: 101.71
D10: 需 | E10: 99.94 | F10: 100.82 | G10: 101.6 | I10: 101.67
B11: IHS | C11: 7.27 | D11: 供 | E11: 103.67 | F11: 102.1 | G11: 101.8 | H11: =G11-G12 -> -2.3 | I11: 103.53
D12: 需 | E12: 101.12 | F12: 101.1 | G12: 104.1 | I12: 103.6
C13: 6.2 | D13: 供 | E13: 103.67 | F13: 102.1 | G13: 102 | H13: -1.6 | I13: 103.53
D14: 需 | E14: 101.12 | F14: 101.1 | G14: 103.6 | I14: 103.6
B15: Woodmac | C15: 7.8 | D15: 供 | E15: 102.06 | F15: 100.85 | G15: 100.38 | H15: =G15-G16 -> -2.34 | I15: 102.34
D16: 需 | E16: 99.58 | F16: 100.95 | G16: 102.72 | I16: 102.9
C17: 6.8 | D17: 供 | E17: 102.06 | F17: 100.85 | G17: 100.95 | H17: -1.89 | I17: 102.34
D18: 需 | E18: 99.58 | F18: 100.95 | G18: 102.84 | I18: 102.9
B19: Rystad | C19: 7.17 | D19: 供 | E19: 101.01 | F19: 100.72 | G19: 100.52 | H19: =G19-G20 -> -3.08 | I19: 101.55
D20: 需 | E20: 101.02 | F20: 101.59 | G20: 103.6 | I20: 103.48
C21: 6.22 | D21: 供 | E21: 101.01 | F21: 100.72 | G21: 100.82 | H21: -2.64 | I21: 101.55
D22: 需 | E22: 101.02 | F22: 101.59 | G22: 103.46 | I22: 103.48

Sheet 202308
B2: 预测机构 | C2: 更新日期 | D2: 供需 | E2: 2023Q1 | F2: 2023Q2 | G2: 2023Q3 | H2: 2023Q3供需差 | I2: 2023Q4
B3: IEA | C3: 8.11 | D3: 供 | E3: 101.4 | F3: 100.6 | G3: 100.8 | H3: =G3-G4 -> -2.1 | I3: 101.1
D4: 需 | E4: 100.5 | F4: 101.3 | G4: 102.9 | I4: 103.1
C5: 7.13 | D5: 供 | E5: 101.4 | F5: 100.6 | G5: 101.1 | H5: -2 | I5: 101.1
D6: 需 | E6: 100.5 | F6: 101.3 | G6: 103.1 | I6: 103.1
B7: EIA | C7: 8.8 | D7: 供 | E7: 100.96 | F7: 101.11 | G7: 101.03 | H7: =G7-G8 -> -0.64 | I7: 101.71
D8: 需 | E8: 99.94 | F8: 100.82 | G8: 101.67 | I8: 101.67
C9: 7.6 | D9: 供 | E9: 100.96 | F9: 101.11 | G9: 100.8 | H9: -0.9 | I9: 101.71
D10: 需 | E10: 99.94 | F10: 100.82 | G10: 101.7 | I10: 101.67
B11: IHS | C11: 7.27 | D11: 供 | E11: 103.67 | F11: 102.1 | G11: 101.8 | H11: =G11-G12 -> -2.3 | I11: 103.53
D12: 需 | E12: 101.12 | F12: 101.1 | G12: 104.1 | I12: 103.6
C13: 7.27 | D13: 供 | E13: 103.67 | F13: 102.1 | G13: 101.8 | H13: -2.3 | I13: 103.53
D14: 需 | E14: 101.12 | F14: 101.1 | G14: 104.1 | I14: 103.6
B15: Woodmac | C15: 7.8 | D15: 供 | E15: 102.06 | F15: 100.85 | G15: 100 | H15: =G15-G16 -> -2.61 | I15: 102.34
D16: 需 | E16: 99.58 | F16: 100.95 | G16: 102.61 | I16: 102.9
C17: 7.8 | D17: 供 | E17: 102.06 | F17: 100.85 | G17: 100.38 | H17: -2.34 | I17: 102.34
D18: 需 | E18: 99.58 | F18: 100.95 | G18: 102.72 | I18: 102.9
B19: Rystad | C19: 7.17 | D19: 供 | E19: 101.01 | F19: 100.72 | G19: 100.52 | H19: =G19-G20 -> -3.08 | I19: 101.55
D20: 需 | E20: 101.02 | F20: 101.59 | G20: 103.6 | I20: 103.48
C21: 7.17 | D21: 供 | E21: 101.01 | F21: 100.72 | G21: 100.52 | H21: -3.08 | I21: 101.55
D22: 需 | E22: 101.02 | F22: 101.59 | G22: 103.6 | I22: 103.48

Sheet 202309
C4: IEA | D4: 7.13 | I4: -2 | K4: -2
E5: 需 | F5: 100.5 | G5: 101.3 | H5: 103.1 | J5: 103.1
D6: 8.11 | E6: 供 | F6: 101.8 | G6: 101.5 | H6: 100.8 | I6: -2.1 | J6: 101.9 | K6: -1.2
E7: 需 | F7: 100.6 | G7: 102 | H7: 102.9 | J7: 103.1
C8: EIA | D8: 7.6 | E8: 供 | F8: 100.96 | G8: 101.11 | H8: 100.8 | I8: -0.9 | J8: 101.71 | K8: 0.04
E9: 需 | F9: 99.94 | G9: 100.82 | H9: 101.7 | J9: 101.67
D10: 8.8 | E10: 供 | F10: 101 | G10: 101.31 | H10: 101.03 | I10: -0.64 | J10: 101.84 | K10: -0.11
E11: 需 | F11: 100.21 | G11: 100.97 | H11: 101.67 | J11: 101.95
C12: IHS | D12: 7.27 | E12: 供 | F12: 103.67 | G12: 102.1 | H12: 101.8 | I12: -2.3 | J12: 103.53 | K12: -0.07
E13: 需 | F13: 101.12 | G13: 101.1 | H13: 104.1 | J13: 103.6
D14: 8.7 | E14: 供 | F14: 103.5 | G14: 102.3 | H14: 101.8 | I14: -2.3 | J14: 103.4 | K14: -0.8
E15: 需 | F15: 100.6 | G15: 101.7 | H15: 104.1 | J15: 104.2
C16: Woodmac | D16: 7.8 | E16: 供 | F16: 102.06 | G16: 100.85 | H16: 100.38 | I16: -2.34 | J16: 102.34 | K16: -0.56
E17: 需 | F17: 99.58 | G17: 100.95 | H17: 102.72 | J17: 102.9
D18: 8.8 | E18: 供 | F18: 102.01 | G18: 100.92 | H18: 100 | I18: -2.61 | J18: 101.82 | K18: -0.97
E19: 需 | F19: 99.68 | G19: 100.45 | H19: 102.61 | J19: 102.79
C20: Rystad | D20: 7.17 | E20: 供 | F20: 101.01 | G20: 100.72 | H20: 100.52 | I20: -3.08 | J20: 101.55 | K20: -1.93
E21: 需 | F21: 101.02 | G21: 101.59 | H21: 103.6 | J21: 103.48
D22: 8.29 | E22: 供 | F22: 101.04 | G22: 100.85 | H22: 100.58 | I22: -2.89 | J22: 101.75 | K22: -1.76
E23: 需 | F23: 101.77 | G23: 103.24 | H23: 103.47 | J23: 103.51

Sheet 202310
B2: 预测机构 | C2: 更新日期 | D2: 供需 | E2: 2023Q1 | F2: 2023Q2 | G2: 2023Q3 | H2: 2023Q4 | I2: 2023Q3供需差
B3: IEA | C3: 9.13 | D3: 供 | E3: 101.85 | F3: 101.8 | G3: 101.3 | H3: 101.4 | I3: =H3-H4 -> -1.09
D4: 需 | E4: 100.39 | F4: 101.71 | G4: 102.64 | H4: 102.49
C5: 8.11 | D5: 供 | E5: 101.8 | F5: 101.5 | G5: 100.8 | H5: 101.9 | I5: -1.2
D6: 需 | E6: 100.6 | F6: 102 | G6: 102.9 | H6: 103.1
B7: EIA | C7: 9.7 | D7: 供 | E7: 100.96 | F7: 101.11 | G7: 101.03 | H7: 101.52 | I7: =H7-H8 -> -0.23
D8: 需 | E8: 99.94 | F8: 100.82 | G8: 101.67 | H8: 101.75
C9: 8.8 | D9: 供 | E9: 101 | F9: 101.31 | G9: 101.03 | H9: 101.84 | I9: -0.11
D10: 需 | E10: 100.21 | F10: 100.97 | G10: 101.67 | H10: 101.95
B11: IHS | C11: 8.3 | D11: 供 | E11: 103.67 | F11: 102.1 | G11: 101.8 | H11: 102.94 | I11: =H11-H12 -> -1.19
D12: 需 | E12: 101.12 | F12: 101.1 | G12: 104.1 | H12: 104.13
C13: 8.7 | D13: 供 | E13: 103.5 | F13: 102.3 | G13: 101.8 | H13: 103.4 | I13: -0.8
D14: 需 | E14: 100.6 | F14: 101.7 | G14: 104.1 | H14: 104.2
B15: Woodmac | C15: 9.8 | D15: 供 | E15: 102.06 | F15: 100.85 | G15: 100 | H15: 101.37 | I15: =H15-H16 -> -1.13
D16: 需 | E16: 99.58 | F16: 100.95 | G16: 102.61 | H16: 102.5
C17: 8.8 | D17: 供 | E17: 102.01 | F17: 100.92 | G17: 100 | H17: 101.82 | I17: -0.97
D18: 需 | E18: 99.68 | F18: 100.45 | G18: 102.61 | H18: 102.79
B19: Rystad | C19: 9.29 | D19: 供 | E19: 101.01 | F19: 100.72 | G19: 100.52 | H19: 101.55 | I19: =H19-H20 -> -1.93
D20: 需 | E20: 101.02 | F20: 101.59 | G20: 103.6 | H20: 103.48
C21: 8.29 | D21: 供 | E21: 101.04 | F21: 100.85 | G21: 100.58 | H21: 101.75 | I21: -1.76
D22: 需 | E22: 101.77 | F22: 103.24 | G22: 103.47 | H22: 103.51

Sheet 202311
B2: 预测机构 | C2: 更新日期 | D2: 供需 | E2: 2023Q1 | F2: 2023Q2 | G2: 2023Q3 | H2: 2023Q4 | I2: 2023Q4供需差
B3: IEA | C3: 10.12 | D3: 供 | E3: 101.85 | F3: 101.8 | G3: 101.3 | H3: 101.3 | I3: =H3-H4 -> -1.28
D4: 需 | E4: 100.39 | F4: 101.71 | G4: 102.64 | H4: 102.58
C5: 9.13 | D5: 供 | E5: 101.85 | F5: 101.8 | G5: 101.3 | H5: 101.4 | I5: -1.09
D6: 需 | E6: 100.39 | F6: 101.71 | G6: 102.64 | H6: 102.49
B7: EIA | C7: 9.7 | D7: 供 | E7: 100.96 | F7: 101.11 | G7: 101.03 | H7: 101.56 | I7: =H7-H8 -> -0.06
D8: 需 | E8: 99.94 | F8: 100.82 | G8: 101.67 | H8: 101.62
C9: 9.7 | D9: 供 | E9: 100.96 | F9: 101.11 | G9: 101.03 | H9: 101.52 | I9: -0.23
D10: 需 | E10: 99.94 | F10: 100.82 | G10: 101.67 | H10: 101.75
B11: IHS | C11: 10.3 | D11: 供 | E11: 103.67 | F11: 102.1 | G11: 101.8 | H11: 103.17 | I11: =H11-H12 -> 0.07
D12: 需 | E12: 101.12 | F12: 101.1 | G12: 104.1 | H12: 103.1
C13: 9.3 | D13: 供 | E13: 103.67 | F13: 102.1 | G13: 101.8 | H13: 102.94 | I13: -1.19
D14: 需 | E14: 101.12 | F14: 101.1 | G14: 104.1 | H14: 104.13
B15: Woodmac | C15: 10.6 | D15: 供 | E15: 102.06 | F15: 100.85 | G15: 100 | H15: 101.53 | I15: =H15-H16 -> -1.24
D16: 需 | E16: 99.58 | F16: 100.95 | G16: 102.61 | H16: 102.77
C17: 9.8 | D17: 供 | E17: 102.06 | F17: 100.85 | G17: 100 | H17: 101.37 | I17: -1.13
D18: 需 | E18: 99.58 | F18: 100.95 | G18: 102.61 | H18: 102.5
B19: Rystad | C19: 10.7 | D19: 供 | E19: 101.01 | F19: 100.72 | G19: 100.52 | H19: 101.37 | I19: =H19-H20 -> -1.32
D20: 需 | E20: 101.02 | F20: 101.59 | G20: 103.6 | H20: 102.69
C21: 9.29 | D21: 供 | E21: 101.01 | F21: 100.72 | G21: 100.52 | H21: 101.55 | I21: -1.93
D22: 需 | E22: 101.02 | F22: 101.59 | G22: 103.6 | H22: 103.48

Sheet 202312
B2: 预测机构 | C2: 更新日期 | D2: 供需 | E2: 2023Q1 | F2: 2023Q2 | G2: 2023Q3 | H2: 2023Q4 | I2: 2023Q4供需差
B3: IEA | C3: 11.14 | D3: 供 | E3: 101.85 | F3: 101.8 | G3: 101.3 | H3: 101.8 | I3: =H3-H4 -> -1
D4: 需 | E4: 100.39 | F4: 101.71 | G4: 102.64 | H4: 102.8
C5: 10.12 | D5: 供 | E5: 101.85 | F5: 101.8 | G5: 101.3 | H5: 101.3 | I5: -1.28
D6: 需 | E6: 100.39 | F6: 101.71 | G6: 102.64 | H6: 102.58
B7: EIA | C7: 11.7 | D7: 供 | E7: 100.96 | F7: 101.11 | G7: 101.03 | H7: 102.05 | I7: =H7-H8 -> 0.2
D8: 需 | E8: 99.94 | F8: 100.82 | G8: 101.67 | H8: 101.85
C9: 10.7 | D9: 供 | E9: 100.96 | F9: 101.11 | G9: 101.03 | H9: 101.56 | I9: -0.06
D10: 需 | E10: 99.94 | F10: 100.82 | G10: 101.67 | H10: 101.62
B11: IHS | C11: 10.28 | D11: 供 | E11: 103.67 | F11: 102.1 | G11: 101.8 | H11: 103.22 | I11: =H11-H12 -> 0.13
D12: 需 | E12: 101.12 | F12: 101.1 | G12: 104.1 | H12: 103.09
C13: 10.3 | D13: 供 | E13: 103.67 | F13: 102.1 | G13: 101.8 | H13: 103.17 | I13: 0.07
D14: 需 | E14: 101.12 | F14: 101.1 | G14: 104.1 | H14: 103.1
B15: Rystad | C15: 11.7 | D15: 供 | E15: 101.01 | F15: 100.72 | G15: 100.52 | H15: 101.35 | I15: =H15-H16 -> -1.42
D16: 需 | E16: 101.02 | F16: 101.59 | G16: 103.6 | H16: 102.77
C17: 10.7 | D17: 供 | E17: 101.01 | F17: 100.72 | G17: 100.52 | H17: 101.37 | I17: -1.32
D18: 需 | E18: 101.02 | F18: 101.59 | G18: 103.6 | H18: 102.69

Sheet 202401
C3: 预测机构 | D3: 更新日期 | E3: 供需 | F3: 2023Q4 | G3: 2023Q4供需差 | H3: 2024Q1 | I3: 2024Q1供需差
C4: IEA | D4: 12.14 | E4: 供 | F4: 101.95 | G4: -0.25 | H4: 101.35 | I4: -0.05
E5: 需 | F5: 102.2 | H5: 101.4
D6: 11.14 | E6: 供 | F6: 101.95 | G6: -0.25 | H6: 101.35 | I6: -0.05
E7: 需 | F7: 102.2 | H7: 101.4
C8: EIA | D8: 12.7 | E8: 供 | F8: 102.24 | G8: 0.62 | H8: 101.19 | I8: -0.84
E9: 需 | F9: 101.62 | H9: 102.03
D10: 11.7 | E10: 供 | F10: 100.96 | G10: 101.11 | H10: 101.56 | I10: -0.06
E11: 需 | F11: 99.94 | G11: 100.82 | H11: 101.62
C12: IHS | D12: 11.29 | E12: 供 | F12: 103.8 | G12: 0.8 | H12: 104.2 | I12: 2.2
E13: 需 | F13: 103 | H13: 102
D14: 10.3 | E14: 供 | F14: 103.67 | G14: 102.1 | H14: 103.17 | I14: 0.07
E15: 需 | F15: 101.12 | H15: 103.1
C16: Rystad | D16: 11.7 | E16: 供 | F16: 101.01 | G16: 100.72 | H16: 101.35 | I16: -1.42
E17: 需 | F17: 101.02 | G17: 101.59 | H17: 102.77
D18: 10.7 | E18: 供 | F18: 101.01 | G18: 100.72 | H18: 101.37 | I18: -1.32
E19: 需 | F19: 101.02 | G19: 101.59 | H19: 102.69

Sheet 202402
C3: 预测机构 | D3: 更新日期 | E3: 供需 | F3: 2024Q1 | G3: 2024Q1供需差 | H3: 2024年 | I3: 2024年供需差
C4: IEA | D4: 1.14 | E4: 供 | F4: 101.6 | G4: =F4-F5 -> -0.1 | H4: 103.5 | I4: =H4-H5 -> 0.5
E5: 需 | F5: 101.7 | H5: 103
D6: 12.14 | E6: 供 | F6: 101.3 | G6: =F6-F7 -> -0.1 | H6: 103.2 | I6: =H6-H7 -> 0.4
E7: 需 | F7: 101.4 | H7: 102.8
C8: EIA | D8: 1.7 | E8: 供 | F8: 101.3 | G8: =F8-F9 -> -0.9 | H8: 102.3 | I8: =H8-H9 -> -0.2
E9: 需 | F9: 102.2 | H9: 102.5
D10: 12.7 | E10: 供 | F10: 101.2 | G10: =F10-F11 -> -0.8 | H10: 102.2 | I10: =H10-H11 -> -0.1
E11: 需 | F11: 102 | H11: 102.3
C12: IHS | D12: 1.3 | E12: 供 | F12: 104.3 | G12: =F12-F13 -> 1.9 | H12: 105.3 | I12: =H12-H13 -> 0.9
E13: 需 | F13: 102.4 | H13: 104.4
D14: 12.21 | E14: 供 | F14: 104.2 | G14: =F14-F15 -> 2.2 | H14: 104.9 | I14: =H14-H15 -> 1.1
E15: 需 | F15: 102 | H15: 103.8
C16: WM | D16: 1.7 | E16: 供 | F16: 102.3 | G16: =F16-F17 -> 0.8 | H16: 103.1 | I16: =H16-H17 -> -0.3
E17: 需 | F17: 101.5 | H17: 103.4
D18: 12.7 | E18: 供 | F18: 102.1 | G18: =F18-F19 -> 0.1 | H18: 103.2 | I18: =H18-H19 -> -0.5
E19: 需 | F19: 102 | H19: 103.7
C20: Rystad | D20: 1.11 | E20: 供 | F20: 101.1 | G20: =F20-F21 -> -1.5 | H20: 103.3 | I20: =H20-H21 -> -0.3
E21: 需 | F21: 102.6 | H21: 103.6
D22: 12.6 | E22: 供 | F22: 101.2 | G22: =F22-F23 -> -1.6 | H22: 103.2 | I22: =H22-H23 -> -0.5
E23: 需 | F23: 102.8 | H23: 103.7

Sheet 202403
C3: 预测机构 | D3: 更新日期 | E3: 供需 | F3: 2024Q1 | G3: 2024Q1供需差 | H3: 2024年 | I3: 2024年供需差
C4: IEA | D4: 2.15 | E4: 供 | F4: 101.9 | G4: =F4-F5 -> 0.2 | H4: 103.8 | I4: =H4-H5 -> 0.8
E5: 需 | F5: 101.7 | H5: 103
D6: 1.14 | E6: 供 | F6: 101.6 | G6: -0.1 | H6: 103.5 | I6: 0.5
E7: 需 | F7: 101.7 | H7: 103
C8: EIA | D8: 2.7 | E8: 供 | F8: 101.2 | G8: =F8-F9 -> -0.8 | H8: 102.3 | I8: =H8-H9 -> -0.1
E9: 需 | F9: 102 | H9: 102.4
D10: 1.7 | E10: 供 | F10: 101.3 | G10: -0.9 | H10: 102.3 | I10: -0.2
E11: 需 | F11: 102.2 | H11: 102.5
C12: IHS | D12: 2.28 | E12: 供 | F12: 104.4 | G12: =F12-F13 -> 1.9 | H12: 105.3 | I12: =H12-H13 -> 0.9
E13: 需 | F13: 102.5 | H13: 104.4
D14: 1.3 | E14: 供 | F14: 104.3 | G14: 1.9 | H14: 105.3 | I14: 0.9
E15: 需 | F15: 102.4 | H15: 104.4
C16: WM | D16: 2.8 | E16: 供 | F16: 102.1 | G16: =F16-F17 -> 1.9 | H16: 103 | I16: =H16-H17 -> 1.4
E17: 需 | F17: 100.2 | H17: 101.6
D18: 1.7 | E18: 供 | F18: 102.3 | G18: 0.8 | H18: 103.1 | I18: -0.3
E19: 需 | F19: 101.5 | H19: 103.4
C20: Rystad | D20: 2.13 | E20: 供 | F20: 101.3 | G20: =F20-F21 -> -1.6 | H20: 103.3 | I20: =H20-H21 -> -0.8
E21: 需 | F21: 102.9 | H21: 104.1
D22: 1.11 | E22: 供 | F22: 101.1 | G22: -1.5 | H22: 103.3 | I22: -0.3
E23: 需 | F23: 102.6 | H23: 103.6

Sheet 202404
C3: 预测机构 | D3: 更新日期 | E3: 供需 | F3: 2024Q2 | G3: 2024Q2供需差 | H3: 2024年 | I3: 2024年供需差
C4: IEA | D4: 3.14 | E4: 供 | F4: 102.7 | G4: =F4-F5 -> -0.31 | H4: 102.86 | I4: =H4-H5 -> -0.32
E5: 需 | F5: 103.01 | H5: 103.18
D6: 2.15 | E6: 供 | H6: 103.8 | I6: 0.8
E7: 需 | H7: 103
C8: EIA | D8: 3.7 | E8: 供 | F8: 101.35 | G8: =F8-F9 -> -0.87 | H8: 102.16 | I8: =H8-H9 -> -0.28
E9: 需 | F9: 102.22 | H9: 102.44
D10: 2.7 | E10: 供 | H10: 102.3 | I10: -0.1
E11: 需 | H11: 102.4
C12: IHS | D12: 2.28 | E12: 供 | F12: 104 | G12: =F12-F13 -> -0.1 | H12: 105.3 | I12: =H12-H13 -> 0.8
E13: 需 | F13: 104.1 | H13: 104.5
D14: 2.28 | E14: 供 | H14: 105.3 | I14: 0.9
E15: 需 | H15: 104.4
C16: WM | D16: 3.7 | E16: 供 | F16: 101.56 | G16: =F16-F17 -> -1.66 | H16: 102.65 | I16: =H16-H17 -> -0.94
E17: 需 | F17: 103.22 | H17: 103.59
D18: 2.8 | E18: 供 | H18: 103 | I18: 1.4
E19: 需 | H19: 101.6
C20: Rystad | D20: 3.15 | E20: 供 | F20: 101.86 | G20: =F20-F21 -> -0.71 | H20: 102.98 | I20: =H20-H21 -> -0.72
E21: 需 | F21: 102.57 | H21: 103.7
D22: 2.13 | E22: 供 | H22: 103.3 | I22: -0.8
E23: 需 | H23: 104.1

Sheet 202405
C3: 预测机构 | D3: 更新日期 | E3: 供需 | F3: 2024Q2 | G3: 2024Q2供需差 | H3: 2024年 | I3: 2024年供需差
C4: IEA | D4: 4.12 | E4: 供 | F4: 102.7 | G4: =F4-F5 -> -0.3 | H4: 102.9 | I4: =H4-H5 -> -0.3
E5: 需 | F5: 103 | H5: 103.2
D6: 3.14 | E6: 供 | F6: 102.7 | G6: -0.31 | H6: 102.86 | I6: -0.32
E7: 需 | F7: 103.01 | H7: 103.18
C8: EIA | D8: 4.7 | E8: 供 | F8: 101.79 | G8: =F8-F9 -> -0.94 | H8: 102.65 | I8: =H8-H9 -> -0.26
E9: 需 | F9: 102.73 | H9: 102.91
D10: 3.7 | E10: 供 | F10: 101.35 | G10: -0.87 | H10: 102.16 | I10: -0.28
E11: 需 | F11: 102.22 | H11: 102.44
C12: IHS | D12: 3.28 | E12: 供 | F12: 104.88 | G12: =F12-F13 -> 0.94 | H12: 105.16 | I12: =H12-H13 -> 0.71
E13: 需 | F13: 103.94 | H13: 104.45
D14: 2.28 | E14: 供 | F14: 104 | G14: -0.1 | H14: 105.3 | I14: 0.8
E15: 需 | F15: 104.1 | H15: 104.5
C16: WM | D16: 4.7 | E16: 供 | F16: 101.49 | G16: =F16-F17 -> -1.61 | H16: 102.54 | I16: =H16-H17 -> -1.08
E17: 需 | F17: 103.1 | H17: 103.62
D18: 3.7 | E18: 供 | F18: 101.56 | G18: -1.66 | H18: 102.65 | I18: -0.94
E19: 需 | F19: 103.22 | H19: 103.59
C20: Rystad | D20: 4.17 | E20: 供 | F20: 101.84 | G20: =F20-F21 -> -0.66 | H20: 102.92 | I20: =H20-H21 -> -0.68
E21: 需 | F21: 102.5 | H21: 103.6
D22: 3.15 | E22: 供 | F22: 101.86 | G22: -0.71 | H22: 102.98 | I22: -0.72
E23: 需 | F23: 102.57 | H23: 103.7

Sheet 202408
C3: 预测机构 | D3: 更新日期 | E3: 供需 | F3: 2024Q3 | G3: 2024Q3供需差 | H3: 2024年 | I3: 2024年供需差
C4: IEA | D4: 7.11 | E4: 供 | F4: 103.5 | G4: =F4-F5 -> -0.6 | H4: 103 | I4: =H4-H5 -> -0.1
E5: 需 | F5: 104.1 | H5: 103.1
D6: 6.12 | E6: 供 | F6: 103.4 | G6: -0.8 | H6: 102.9 | I6: -0.3
E7: 需 | F7: 104.2 | H7: 103.2
C8: EIA | D8: 7.9 | E8: 供 | F8: 102.73 | G8: =F8-F9 -> -0.84 | H8: 102.42 | I8: =H8-H9 -> -0.5
E9: 需 | F9: 103.57 | H9: 102.92
D10: 6.11 | E10: 供 | F10: 103.01 | G10: -0.57 | H10: 102.57 | I10: -0.42
E11: 需 | F11: 103.58 | H11: 102.99
C12: IHS | D12: 7.3 | E12: 供 | F12: 103.82 | G12: =F12-F13 -> -2.59 | H12: 103.72 | I12: =H12-H13 -> -1
E13: 需 | F13: 106.41 | H13: 104.72
D14: 6.30 | E14: 供 | F14: 104.65 | G14: -1.57 | H14: 104.19 | I14: -0.48
E15: 需 | F15: 106.22 | H15: 104.67
C16: WM | D16: 7.7 | E16: 供 | F16: 101.85 | G16: =F16-F17 -> -2.71 | H16: 102.2 | I16: =H16-H17 -> -1.04
E17: 需 | F17: 104.56 | H17: 103.24
D18: 6.7 | E18: 供 | F18: 101.21 | G18: -1.55 | H18: 102.14 | I18: -1.15
E19: 需 | F19: 102.76 | H19: 103.29
C20: Rystad | D20: 7.19 | E20: 供 | F20: 103 | G20: =F20-F21 -> -2.23 | H20: 102.7 | I20: =H20-H21 -> -1
E21: 需 | F21: 105.23 | H21: 103.7
D22: 6.20 | E22: 供 | F22: 102.8 | G22: -2.5 | H22: 102.33 | I22: -1.37
E23: 需 | F23: 105.3 | H23: 103.7

Sheet 202406
C3: 预测机构 | D3: 更新日期 | E3: 供需 | F3: 2024Q2 | G3: 2024Q2供需差 | H3: 2024年 | I3: 2024年供需差
C4: IEA | D4: 5.15 | E4: 供 | F4: 102.3 | G4: =F4-F5 -> -0.6 | H4: 102.7 | I4: =H4-H5 -> -0.5
E5: 需 | F5: 102.9 | H5: 103.2
D6: 4.12 | E6: 供 | F6: 102.7 | G6: -0.3 | H6: 102.9 | I6: -0.3
E7: 需 | F7: 103 | H7: 103.2
C8: EIA | D8: 5.7 | E8: 供 | F8: 102.05 | G8: =F8-F9 -> -0.36 | H8: 102.76 | I8: =H8-H9 -> -0.08
E9: 需 | F9: 102.41 | H9: 102.84
D10: 4.7 | E10: 供 | F10: 101.79 | G10: -0.94 | H10: 102.65 | I10: -0.26
E11: 需 | F11: 102.73 | H11: 102.91
C12: IHS | D12: 5.3 | E12: 供 | F12: 104.1 | G12: =F12-F13 -> -0.1 | H12: 104.2 | I12: =H12-H13 -> -0.6
E13: 需 | F13: 104.2 | H13: 104.8
D14: 3.28 | E14: 供 | F14: 104.88 | G14: 0.94 | H14: 105.16 | I14: 0.71
E15: 需 | F15: 103.94 | H15: 104.45
C16: WM | D16: 5.1 | E16: 供 | F16: 101.61 | G16: =F16-F17 -> -1.54 | H16: 102.5 | I16: =H16-H17 -> -1.05
E17: 需 | F17: 103.15 | H17: 103.55
D18: 4.7 | E18: 供 | F18: 101.49 | G18: -1.61 | H18: 102.54 | I18: -1.08
E19: 需 | F19: 103.1 | H19: 103.62
C20: Rystad | D20: 5.8 | E20: 供 | F20: 101.87 | G20: =F20-F21 -> -0.82 | H20: 102.95 | I20: =H20-H21 -> -0.72
E21: 需 | F21: 102.69 | H21: 103.67
D22: 4.17 | E22: 供 | F22: 101.84 | G22: -0.66 | H22: 102.92 | I22: -0.68
E23: 需 | F23: 102.5 | H23: 103.6

Sheet 202407
C3: 预测机构 | D3: 更新日期 | E3: 供需 | F3: 2024Q3 | G3: 2024Q3供需差 | H3: 2024年 | I3: 2024年供需差
C4: IEA | D4: 6.12 | E4: 供 | F4: 103.4 | G4: =F4-F5 -> -0.8 | H4: 102.9 | I4: =H4-H5 -> -0.3
E5: 需 | F5: 104.2 | H5: 103.2
D6: 5.15 | E6: 供 | F6: 103.3 | G6: =F6-F7 -> -0.8 | H6: 102.7 | I6: =H6-H7 -> -0.5
E7: 需 | F7: 104.1 | H7: 103.2
C8: EIA | D8: 6.11 | E8: 供 | F8: 103.01 | G8: =F8-F9 -> -0.57 | H8: 102.57 | I8: =H8-H9 -> -0.42
E9: 需 | F9: 103.58 | H9: 102.99
D10: 5.7 | E10: 供 | F10: 103.46 | G10: =F10-F11 -> 0.1 | H10: 102.76 | I10: =H10-H11 -> -0.08
E11: 需 | F11: 103.36 | H11: 102.84
C12: IHS | D12: 6.3 | E12: 供 | F12: 104.65 | G12: =F12-F13 -> -1.57 | H12: 104.19 | I12: =H12-H13 -> -0.48
E13: 需 | F13: 106.22 | H13: 104.67
D14: 5.30 | E14: 供 | F14: 104.77 | G14: =F14-F15 -> -1.28 | H14: 104.21 | I14: =H14-H15 -> -0.57
E15: 需 | F15: 106.05 | H15: 104.78
C16: WM | D16: 6.7 | E16: 供 | F16: 101.21 | G16: =F16-F17 -> -1.55 | H16: 102.14 | I16: =H16-H17 -> -1.15
E17: 需 | F17: 102.76 | H17: 103.29
D18: 5.10 | E18: 供 | F18: 102.66 | G18: =F18-F19 -> -2.07 | H18: 102.5 | I18: =H18-H19 -> -1.05
E19: 需 | F19: 104.73 | H19: 103.55
C20: Rystad | D20: 6.20 | E20: 供 | F20: 102.8 | G20: =F20-F21 -> -2.5 | H20: 102.33 | I20: =H20-H21 -> -1.37
E21: 需 | F21: 105.3 | H21: 103.7
D22: 5.8 | E22: 供 | F22: 104.18 | G22: =F22-F23 -> -0.85 | H22: 102.95 | I22: =H22-H23 -> -0.72
E23: 需 | F23: 105.03 | H23: 103.67

Sheet 202409
C3: 预测机构 | D3: 更新日期 | E3: 供需 | F3: 2024Q3 | G3: 2024Q3供需差 | H3: 2024年 | I3: 2024年供需差
C4: IEA | D4: 8.13 | E4: 供 | F4: 102.66 | G4: =F4-F5 -> -0.89 | H4: 102.36 | I4: =H4-H5 -> -0.58
E5: 需 | F5: 103.55 | H5: 102.94
D6: 7.11 | E6: 供 | F6: 103.5 | G6: -0.6 | H6: 103 | I6: -0.1
E7: 需 | F7: 104.1 | H7: 103.1
C8: EIA | D8: 8.6 | E8: 供 | F8: 102.73 | G8: =F8-F9 -> -0.84 | H8: 102.42 | I8: =H8-H9 -> -0.5
E9: 需 | F9: 103.57 | H9: 102.92
D10: 7.9 | E10: 供 | F10: 102.73 | G10: -0.84 | H10: 102.42 | I10: -0.5
E11: 需 | F11: 103.57 | H11: 102.92
C12: IHS | D12: 9.01 | E12: 供 | F12: 104.82 | G12: =F12-F13 -> -1.35 | H12: 104.26 | I12: =H12-H13 -> -0.32
E13: 需 | F13: 106.17 | H13: 104.58
D14: 7.30 | E14: 供 | F14: 103.82 | G14: -2.59 | H14: 103.72 | I14: -1
E15: 需 | F15: 106.41 | H15: 104.72
C16: WM | D16: 8.8 | E16: 供 | F16: 101.84 | G16: =F16-F17 -> -2.62 | H16: 102.26 | I16: =H16-H17 -> -1
E17: 需 | F17: 104.46 | H17: 103.26
D18: 7.7 | E18: 供 | F18: 101.85 | G18: -2.71 | H18: 102.2 | I18: -1.04
E19: 需 | F19: 104.56 | H19: 103.24
C20: Rystad | D20: 8.24 | E20: 供 | F20: 103.21 | G20: =F20-F21 -> -1.63 | H20: 102.83 | I20: =H20-H21 -> -0.55
E21: 需 | F21: 104.84 | H21: 103.38
D22: 7.19 | E22: 供 | F22: 103 | G22: -2.23 | H22: 102.7 | I22: -1
E23: 需 | F23: 105.23 | H23: 103.7

Sheet 202410
E2: 2024Q3 | F2: 2024Q4 | G2: 2025Q1 | H2: 2025Q2 | I2: 2025Q3 | J2: 2025Q4
D3: 供应 | E3: 103.28 | F3: 103.8 | G3: 103.81 | H3: 104.99 | I3: 105.2 | J3: 105.4
C4: IEA | D4: 需求 | E4: 103.9 | F4: 103.7 | G4: 102.4 | H4: 103.7 | I4: 104.8 | J4: 104.7
D5: 供需差 | E5: =E3-E4 -> -0.62 | F5: =F3-F4 -> 0.1 | G5: =G3-G4 -> 1.41 | H5: =H3-H4 -> 1.29 | I5: =I3-I4 -> 0.4 | J5: =J3-J4 -> 0.7
C7: EIA | D7: 供应 | E7: 102.47 | F7: 102.47 | G7: 103.18 | H7: 104.26 | I7: 105.39 | J7: 105.54
D8: 需求 | E8: 103.43 | F8: 103.72 | G8: 104.16 | H8: 104.27 | I8: 104.91 | J8: 105.08
D9: 供需差 | E9: =E7-E8 -> -0.96 | F9: =F7-F8 -> -1.25 | G9: =G7-G8 -> -0.98 | H9: =H7-H8 -> -0.01 | I9: =I7-I8 -> 0.48 | J9: =J7-J8 -> 0.46
D11: 供应 | E11: 104.35628 | F11: 105.19893 | G11: 105.19864 | H11: 105.76982 | I11: 106.58146 | J11: 107.12004
C12: IHS | D12: 需求 | E12: 105.88234 | F12: 106.05345 | G12: 104.14795 | H12: 105.09723 | I12: 107.12405 | J12: 106.90736
D13: 供需差 | E13: =E11-E12 -> -1.5260593 | F13: =F11-F12 -> -0.85451874 | G13: =G11-G12 -> 1.0506905 | H13: =H11-H12 -> 0.6725941 | I13: =I11-I12 -> -0.54258224 | J13: =J11-J12 -> 0.21267732
D15: 供应 | E15: 101.84 | F15: 103.26 | G15: 104.22 | H15: 104.57 | I15: 105.26 | J15: 106.45
C16: WM | D16: 需求 | E16: 104.46 | F16: 104.65 | G16: 103.21 | H16: 104.17 | I16: 106.06 | J16: 106.1
D17: 供需差 | E17: =E15-E16 -> -2.62 | F17: =F15-F16 -> -1.39 | G17: =G15-G16 -> 1.01 | H17: =H15-H16 -> 0.4 | I17: =I15-I16 -> -0.8 | J17: =J15-J16 -> 0.35
C19: Rystad | D19: 供应 | E19: 102.54 | F19: 103.06 | G19: 103.42 | H19: 104.94 | I19: 107.09 | J19: 108.24
D20: 需求 | E20: 104.97 | F20: 104.72 | G20: 103.92 | H20: 104.04 | I20: 105.78 | J20: 105.45
D21: 供需差 | E21: =E19-E20 -> -2.43 | F21: =F19-F20 -> -1.66 | G21: =G19-G20 -> -0.5 | H21: =H19-H20 -> 0.9 | I21: =I19-I20 -> 1.31 | J21: =J19-J20 -> 2.79
E23: 2024Q3 | F23: 2024Q4 | G23: 2025Q1 | H23: 2025Q2 | I23: 2025Q3 | J23: 2025Q4
D24: IEA | E24: -0.62 | F24: 0.1 | G24: 1.41 | H24: 1.29 | I24: 0.4 | J24: 0.7
D25: EIA | E25: -0.96 | F25: -1.25 | G25: -0.98 | H25: -0.01 | I25: 0.48 | J25: 0.46
D26: IHS | E26: -1.5260593 | F26: -0.85451874 | G26: 1.0506905 | H26: 0.6725941 | I26: -0.54258224 | J26: 0.21267732
D27: WM | E27: -2.62 | F27: -1.39 | G27: 1.01 | H27: 0.4 | I27: -0.8 | J27: 0.35
D28: Rystad | E28: -2.43 | F28: -1.66 | G28: -0.5 | H28: 0.9 | I28: 1.31 | J28: 2.79

Sheet 202411
D2: 2024Q3 | E2: 2024Q4 | F2: 2025Q1 | G2: 2025Q2 | H2: 2025Q3 | I2: 2025Q4
C3: 供应 | D3: 103.3 | E3: 103.8 | F3: 103.8 | G3: 105 | H3: 105.4 | I3: 105.7
B4: IEA | C4: 需求 | D4: 103.6 | E4: 103.6 | F4: 102.6 | G4: 103.5 | H4: 104.6 | I4: 104.6
C5: 供需差 | D5: =D3-D4 -> -0.3 | E5: =E3-E4 -> 0.2 | F5: =F3-F4 -> 1.2 | G5: =G3-G4 -> 1.5 | H5: =H3-H4 -> 0.8 | I5: =I3-I4 -> 1.1
B7: EIA | C7: 供应 | D7: 102.48 | E7: 103.03 | F7: 103.38 | G7: 104.27 | H7: 105.1 | I7: 105.38
C8: 需求 | D8: 103.25 | E8: 103.64 | F8: 104 | G8: 104.07 | H8: 104.59 | I8: 104.77
C9: 供需差 | D9: =D7-D8 -> -0.77 | E9: =E7-E8 -> -0.61 | F9: =F7-F8 -> -0.62 | G9: =G7-G8 -> 0.2 | H9: =H7-H8 -> 0.51 | I9: =I7-I8 -> 0.61
C11: 供应 | D11: 104.35628 | E11: 105.19893 | F11: 105.19864 | G11: 105.76982 | H11: 106.58146 | I11: 107.12004
B12: S&P | C12: 需求 | D12: 105.88234 | E12: 106.05345 | F12: 104.14795 | G12: 105.09723 | H12: 107.12405 | I12: 106.90736
C13: 供需差 | D13: =D11-D12 -> -1.5260593 | E13: =E11-E12 -> -0.85451874 | F13: =F11-F12 -> 1.0506905 | G13: =G11-G12 -> 0.6725941 | H13: =H11-H12 -> -0.54258224 | I13: =I11-I12 -> 0.21267732
C15: 供应 | D15: 101.93025 | E15: 102.78906 | F15: 103.61485 | G15: 103.92095 | H15: 104.79918 | I15: 106.29265
B16: WM | C16: 需求 | D16: 104.728 | E16: 104.602 | F16: 103.184 | G16: 104.213 | H16: 106.154 | I16: 106.275
C17: 供需差 | D17: =D15-D16 -> -2.7977484 | E17: =E15-E16 -> -1.8129445 | F17: =F15-F16 -> 0.43084783 | G17: =G15-G16 -> -0.2920461 | H17: =H15-H16 -> -1.3548178 | I17: =I15-I16 -> 0.017652217
B19: Rystad | C19: 供应 | D19: 102.23 | E19: 103.09 | F19: 103.46 | G19: 105.06 | H19: 107.36 | I19: 108.59
C20: 需求 | D20: 104.45 | E20: 104.51 | F20: 103.54 | G20: 103.58 | H20: 105.35 | I20: 105.09
C21: 供需差 | D21: =D19-D20 -> -2.22 | E21: =E19-E20 -> -1.42 | F21: =F19-F20 -> -0.08 | G21: =G19-G20 -> 1.48 | H21: =H19-H20 -> 2.01 | I21: =I19-I20 -> 3.5
D23: 2024Q3 | E23: 2024Q4 | F23: 2025Q1 | G23: 2025Q2 | H23: 2025Q3 | I23: 2025Q4
C24: IEA | D24: =D5 -> -0.3 | E24: =E5 -> 0.2 | F24: =F5 -> 1.2 | G24: =G5 -> 1.5 | H24: =H5 -> 0.8 | I24: =I5 -> 1.1
C25: EIA | D25: =D9 -> -0.77 | E25: =E9 -> -0.61 | F25: =F9 -> -0.62 | G25: =G9 -> 0.2 | H25: =H9 -> 0.51 | I25: =I9 -> 0.61
C26: S&P | D26: =D13 -> -1.5260593 | E26: =E13 -> -0.85451874 | F26: =F13 -> 1.0506905 | G26: =G13 -> 0.6725941 | H26: =H13 -> -0.54258224 | I26: =I13 -> 0.21267732
C27: WM | D27: =D17 -> -2.7977484 | E27: =E17 -> -1.8129445 | F27: =F17 -> 0.43084783 | G27: =G17 -> -0.2920461 | H27: =H17 -> -1.3548178 | I27: =I17 -> 0.017652217
C28: Rystad | D28: =D21 -> -2.22 | E28: =E21 -> -1.42 | F28: =F21 -> -0.08 | G28: =G21 -> 1.48 | H28: =H21 -> 2.01 | I28: =I21 -> 3.5

Sheet 202412
D2: 2024Q4 | E2: 2025Q1 | F2: 2025Q2 | G2: 2025Q3 | H2: 2025Q4
C3: 供应 | D3: 103.53 | E3: 103.85 | F3: 104.97 | G3: 105.37 | H3: 105.65
B4: IEA | C4: 需求 | D4: 103.52 | E4: 102.6 | F4: 103.59 | G4: 104.63 | H4: 104.38
C5: 供需差 | D5: =D3-D4 -> 0.01 | E5: =E3-E4 -> 1.25 | F5: =F3-F4 -> 1.38 | G5: =G3-G4 -> 0.74 | H5: =H3-H4 -> 1.27
B7: EIA | C7: 供应 | D7: 103.36 | E7: 103.64 | F7: 104.38 | G7: 105.13 | H7: 105.48
C8: 需求 | D8: 103.67 | E8: 103.92 | F8: 104.02 | G8: 104.71 | H8: 104.8
C9: 供需差 | D9: =D7-D8 -> -0.31 | E9: =E7-E8 -> -0.28 | F9: =F7-F8 -> 0.36 | G9: =G7-G8 -> 0.42 | H9: =H7-H8 -> 0.68
C11: 供应 | D11: 105.19893 | E11: 105.19864 | F11: 105.81 | G11: 106.35 | H11: 106.8
B12: S&P | C12: 需求 | D12: 105.87 | E12: 104.41 | F12: 105.57 | G12: 107.28 | H12: 106.83
C13: 供需差 | D13: =D11-D12 -> -0.67107209 | E13: =E11-E12 -> 0.78864448 | F13: =F11-F12 -> 0.24 | G13: =G11-G12 -> -0.93 | H13: =H11-H12 -> -0.03
C15: 供应 | D15: 103.39 | E15: 103.98 | F15: 104.23 | G15: 105.12 | H15: 106.64
B16: WM | C16: 需求 | D16: 104.48 | E16: 103.31 | F16: 104.21 | G16: 106.2 | H16: 106.14
C17: 供需差 | D17: =D15-D16 -> -1.09 | E17: =E15-E16 -> 0.67 | F17: =F15-F16 -> 0.02 | G17: =G15-G16 -> -1.08 | H17: =H15-H16 -> 0.5
B19: Rystad | C19: 供应 | D19: 102.81 | E19: 103.57 | F19: 104.88 | G19: 106.84 | H19: 107.79
C20: 需求 | D20: 104.26 | E20: 103.5 | F20: 103.72 | G20: 105.43 | H20: 105.15
C21: 供需差 | D21: =D19-D20 -> -1.45 | E21: =E19-E20 -> 0.07 | F21: =F19-F20 -> 1.16 | G21: =G19-G20 -> 1.41 | H21: =H19-H20 -> 2.64
D23: 2024Q4 | E23: 2025Q1 | F23: 2025Q2 | G23: 2025Q3 | H23: 2025Q4
C24: IEA | D24: =D5 -> 0.01 | E24: =E5 -> 1.25 | F24: =F5 -> 1.38 | G24: =G5 -> 0.74 | H24: =H5 -> 1.27
C25: EIA | D25: =D9 -> -0.31 | E25: =E9 -> -0.28 | F25: =F9 -> 0.36 | G25: =G9 -> 0.42 | H25: =H9 -> 0.68
C26: S&P | D26: =D13 -> -0.67107209 | E26: =E13 -> 0.78864448 | F26: =F13 -> 0.24 | G26: =G13 -> -0.93 | H26: =H13 -> -0.03
C27: WM | D27: =D17 -> -1.09 | E27: =E17 -> 0.67 | F27: =F17 -> 0.02 | G27: =G17 -> -1.08 | H27: =H17 -> 0.5
C28: Rystad | D28: =D21 -> -1.45 | E28: =E21 -> 0.07 | F28: =F21 -> 1.16 | G28: =G21 -> 1.41 | H28: =H21 -> 2.64
B31: 与上一月的变化 | D31: 2024Q4 | E31: 2025Q1 | F31: 2025Q2 | G31: 2025Q3 | H31: 2025Q4
C32: IEA | D32: =D24-'202411'!E24 -> -0.19 | E32: =E24-'202411'!F24 -> 0.05 | F32: =F24-'202411'!G24 -> -0.12 | G32: =G24-'202411'!H24 -> -0.06 | H32: =H24-'202411'!I24 -> 0.17
C33: EIA | D33: =D25-'202411'!E25 -> 0.3 | E33: =E25-'202411'!F25 -> 0.34 | F33: =F25-'202411'!G25 -> 0.16 | G33: =G25-'202411'!H25 -> -0.09 | H33: =H25-'202411'!I25 -> 0.07
C34: S&P | D34: =D26-'202411'!E26 -> 0.18344666 | E34: =E26-'202411'!F26 -> -0.26204605 | F34: =F26-'202411'!G26 -> -0.4325941 | G34: =G26-'202411'!H26 -> -0.38741776 | H34: =H26-'202411'!I26 -> -0.24267732
C35: WM | D35: =D27-'202411'!E27 -> 0.72294451 | E35: =E27-'202411'!F27 -> 0.23915217 | F35: =F27-'202411'!G27 -> 0.3120461 | G35: =G27-'202411'!H27 -> 0.2748178 | H35: =H27-'202411'!I27 -> 0.48234778
C36: Rystad | D36: =D28-'202411'!E28 -> -0.03 | E36: =E28-'202411'!F28 -> 0.15 | F36: =F28-'202411'!G28 -> -0.32 | G36: =G28-'202411'!H28 -> -0.6 | H36: =H28-'202411'!I28 -> -0.86

Sheet 202501
D2: 2025Q1 | E2: 2025Q2 | F2: 2025Q3 | G2: 2025Q4
C3: 供应 | D3: 103.6 | E3: 104.8 | F3: 105.3 | G3: 105.6
B4: IEA | C4: 需求 | D4: 102.6 | E4: 103.6 | F4: 104.63 | G4: 104.6
C5: 供需差 | D5: =D3-D4 -> 1 | E5: =E3-E4 -> 1.2 | F5: =F3-F4 -> 0.67 | G5: =G3-G4 -> 1
B7: EIA | C7: 供应 | D7: 103.14 | E7: 103.91 | F7: 104.7 | G7: 105.19
C8: 需求 | D8: 103.87 | E8: 103.96 | F8: 104.68 | G8: 104.81
C9: 供需差 | D9: =D7-D8 -> -0.73 | E9: =E7-E8 -> -0.05 | F9: =F7-F8 -> 0.02 | G9: =G7-G8 -> 0.38
C11: 供应 | D11: 105.19864 | E11: 105.81 | F11: 106.35 | G11: 106.8
B12: S&P | C12: 需求 | D12: 104.24 | E12: 105.3 | F12: 107.09 | G12: 106.81
C13: 供需差 | D13: =D11-D12 -> 0.95864448 | E13: =E11-E12 -> 0.51 | F13: =F11-F12 -> -0.74 | G13: =G11-G12 -> -0.01
C15: 供应 | D15: 103.98 | E15: 104.23 | F15: 105.12 | G15: 106.64
B16: WM | C16: 需求 | D16: 103.03 | E16: 103.92 | F16: 105.91 | G16: 105.79
C17: 供需差 | D17: =D15-D16 -> 0.95 | E17: =E15-E16 -> 0.31 | F17: =F15-F16 -> -0.79 | G17: =G15-G16 -> 0.85
B19: Rystad | C19: 供应 | D19: 103.09 | E19: 104.22 | F19: 106.09 | G19: 106.94
C20: 需求 | D20: 103.52 | E20: 103.82 | F20: 105.55 | G20: 105.17
C21: 供需差 | D21: =D19-D20 -> -0.43 | E21: =E19-E20 -> 0.4 | F21: =F19-F20 -> 0.54 | G21: =G19-G20 -> 1.77
D23: 2025Q1 | E23: 2025Q2 | F23: 2025Q3 | G23: 2025Q4
C24: IEA | D24: =D5 -> 1 | E24: =E5 -> 1.2 | F24: =F5 -> 0.67 | G24: =G5 -> 1
C25: EIA | D25: =D9 -> -0.73 | E25: =E9 -> -0.05 | F25: =F9 -> 0.02 | G25: =G9 -> 0.38
C26: S&P | D26: =D13 -> 0.95864448 | E26: =E13 -> 0.51 | F26: =F13 -> -0.74 | G26: =G13 -> -0.01
C27: WM | D27: =D17 -> 0.95 | E27: =E17 -> 0.31 | F27: =F17 -> -0.79 | G27: =G17 -> 0.85
C28: Rystad | D28: =D21 -> -0.43 | E28: =E21 -> 0.4 | F28: =F21 -> 0.54 | G28: =G21 -> 1.77
B31: 与上一月的变化 | D31: 2025Q1 | E31: 2025Q2 | F31: 2025Q3 | G31: 2025Q4
C32: IEA | D32: =D24-'202412'!E24 -> -0.25 | E32: =E24-'202412'!F24 -> -0.18 | F32: =F24-'202412'!G24 -> -0.07 | G32: =G24-'202412'!H24 -> -0.27
C33: EIA | D33: =D25-'202412'!E25 -> -0.45 | E33: =E25-'202412'!F25 -> -0.41 | F33: =F25-'202412'!G25 -> -0.4 | G33: =G25-'202412'!H25 -> -0.3
C34: S&P | D34: =D26-'202412'!E26 -> 0.17 | E34: =E26-'202412'!F26 -> 0.27 | F34: =F26-'202412'!G26 -> 0.19 | G34: =G26-'202412'!H26 -> 0.02
C35: WM | D35: =D27-'202412'!E27 -> 0.28 | E35: =E27-'202412'!F27 -> 0.29 | F35: =F27-'202412'!G27 -> 0.29 | G35: =G27-'202412'!H27 -> 0.35
C36: Rystad | D36: =D28-'202412'!E28 -> -0.5 | E36: =E28-'202412'!F28 -> -0.76 | F36: =F28-'202412'!G28 -> -0.87 | G36: =G28-'202412'!H28 -> -0.87

Sheet 202502
D2: 2025Q1 | E2: 2025Q2 | F2: 2025Q3 | G2: 2025Q4
C3: 供应 | D3: 103.3 | E3: 104.6 | F3: 105.2 | G3: 105.6
B4: IEA | C4: 需求 | D4: 102.7 | E4: 103.7 | F4: 104.7 | G4: 104.7
C5: 供需差 | D5: =D3-D4 -> 0.6 | E5: =E3-E4 -> 0.9 | F5: =F3-F4 -> 0.5 | G5: =G3-G4 -> 0.9
B7: EIA | C7: 供应 | D7: 103.16 | E7: 104 | F7: 104.88 | G7: 105.36
C8: 需求 | D8: 103.71 | E8: 103.74 | F8: 104.44 | G8: 104.53
C9: 供需差 | D9: =D7-D8 -> -0.55 | E9: =E7-E8 -> 0.26 | F9: =F7-F8 -> 0.44 | G9: =G7-G8 -> 0.83
C11: 供应 | D11: 105.28136 | E11: 105.76561 | F11: 106.27935 | G11: 106.75719
B12: S&P | C12: 需求 | D12: 104.48559 | E12: 105.48427 | F12: 107.29774 | G12: 107.07669
C13: 供需差 | D13: =D11-D12 -> 0.79577282 | E13: =E11-E12 -> 0.28133541 | F13: =F11-F12 -> -1.0183921 | G13: =G11-G12 -> -0.31949879
C15: 供应 | D15: 103.88 | E15: 104.24 | F15: 105.12 | G15: 106.53
B16: WM | C16: 需求 | D16: 102.81 | E16: 103.79 | F16: 105.67 | G16: 105.51
C17: 供需差 | D17: =D15-D16 -> 1.07 | E17: =E15-E16 -> 0.45 | F17: =F15-F16 -> -0.55 | G17: =G15-G16 -> 1.02
B19: Rystad | C19: 供应 | D19: 103.13 | E19: 104.18 | F19: 106.11 | G19: 107.04
C20: 需求 | D20: 103.79 | E20: 103.61 | F20: 105.17 | G20: 105.21
C21: 供需差 | D21: =D19-D20 -> -0.66 | E21: =E19-E20 -> 0.57 | F21: =F19-F20 -> 0.94 | G21: =G19-G20 -> 1.83
D23: 2025Q1 | E23: 2025Q2 | F23: 2025Q3 | G23: 2025Q4
C24: IEA | D24: =D5 -> 0.6 | E24: =E5 -> 0.9 | F24: =F5 -> 0.5 | G24: =G5 -> 0.9
C25: EIA | D25: =D9 -> -0.55 | E25: =E9 -> 0.26 | F25: =F9 -> 0.44 | G25: =G9 -> 0.83
C26: S&P | D26: =D13 -> 0.79577282 | E26: =E13 -> 0.28133541 | F26: =F13 -> -1.0183921 | G26: =G13 -> -0.31949879
C27: WM | D27: =D17 -> 1.07 | E27: =E17 -> 0.45 | F27: =F17 -> -0.55 | G27: =G17 -> 1.02
C28: Rystad | D28: =D21 -> -0.66 | E28: =E21 -> 0.57 | F28: =F21 -> 0.94 | G28: =G21 -> 1.83
B31: 与上一月的变化 | D31: 2025Q1 | E31: 2025Q2 | F31: 2025Q3 | G31: 2025Q4
C32: IEA | D32: =D24-'202501'!D24 -> -0.4 | E32: =E24-'202501'!E24 -> -0.3 | F32: =F24-'202501'!F24 -> -0.17 | G32: =G24-'202501'!G24 -> -0.1
C33: EIA | D33: =D25-'202501'!D25 -> 0.18 | E33: =E25-'202501'!E25 -> 0.31 | F33: =F25-'202501'!F25 -> 0.42 | G33: =G25-'202501'!G25 -> 0.45
C34: S&P | D34: =D26-'202501'!D26 -> -0.16287166 | E34: =E26-'202501'!E26 -> -0.22866459 | F34: =F26-'202501'!F26 -> -0.2783921 | G34: =G26-'202501'!G26 -> -0.30949879
C35: WM | D35: =D27-'202501'!D27 -> 0.12 | E35: =E27-'202501'!E27 -> 0.14 | F35: =F27-'202501'!F27 -> 0.24 | G35: =G27-'202501'!G27 -> 0.17
C36: Rystad | D36: =D28-'202501'!D28 -> -0.23 | E36: =E28-'202501'!E28 -> 0.17 | F36: =F28-'202501'!F28 -> 0.4 | G36: =G28-'202501'!G28 -> 0.06

Sheet 202503
D2: 2025Q1 | E2: 2025Q2 | F2: 2025Q3 | G2: 2025Q4
C3: 供应 | D3: 103.1 | E3: 104.3 | F3: 105 | G3: 105.5
B4: IEA | C4: 需求 | D4: 102.7 | E4: 103.8 | F4: 104.9 | G4: 104.6
C5: 供需差 | D5: =D3-D4 -> 0.4 | E5: =E3-E4 -> 0.5 | F5: =F3-F4 -> 0.1 | G5: =G3-G4 -> 0.9
B7: EIA | C7: 供应 | D7: 103.31 | E7: 104.23 | F7: 105.14 | G7: 105.56
C8: 需求 | D8: 103.88 | E8: 103.76 | F8: 104.47 | G8: 104.47
C9: 供需差 | D9: =D7-D8 -> -0.57 | E9: =E7-E8 -> 0.47 | F9: =F7-F8 -> 0.67 | G9: =G7-G8 -> 1.09
C11: 供应 | D11: 105 | E11: 105.6 | F11: 105.6 | G11: 106.2
B12: S&P | C12: 需求 | D12: 104.7 | E12: 105.6 | F12: 107.3 | G12: 107
C13: 供需差 | D13: =D11-D12 -> 0.3 | E13: =E11-E12 -> 0 | F13: =F11-F12 -> -1.7 | G13: =G11-G12 -> -0.8
C15: 供应 | D15: 103.9 | E15: 104.37 | F15: 105.23 | G15: 106.58
B16: WM | C16: 需求 | D16: 103.05 | E16: 103.96 | F16: 105.76 | G16: 105.58
C17: 供需差 | D17: =D15-D16 -> 0.85 | E17: =E15-E16 -> 0.41 | F17: =F15-F16 -> -0.53 | G17: =G15-G16 -> 1
B19: Rystad | C19: 供应 | D19: 103.03 | E19: 103.98 | F19: 105.7 | G19: 106.93
C20: 需求 | D20: 103.84 | E20: 103.6 | F20: 105.27 | G20: 105.12
C21: 供需差 | D21: =D19-D20 -> -0.81 | E21: =E19-E20 -> 0.38 | F21: =F19-F20 -> 0.43 | G21: =G19-G20 -> 1.81
D23: 2025Q1 | E23: 2025Q2 | F23: 2025Q3 | G23: 2025Q4
C24: IEA | D24: =D5 -> 0.4 | E24: =E5 -> 0.5 | F24: =F5 -> 0.1 | G24: =G5 -> 0.9
C25: EIA | D25: =D9 -> -0.57 | E25: =E9 -> 0.47 | F25: =F9 -> 0.67 | G25: =G9 -> 1.09
C26: S&P | D26: =D13 -> 0.3 | E26: =E13 -> 0 | F26: =F13 -> -1.7 | G26: =G13 -> -0.8
C27: WM | D27: =D17 -> 0.85 | E27: =E17 -> 0.41 | F27: =F17 -> -0.53 | G27: =G17 -> 1
C28: Rystad | D28: =D21 -> -0.81 | E28: =E21 -> 0.38 | F28: =F21 -> 0.43 | G28: =G21 -> 1.81
B31: 与上一月的变化 | D31: 2025Q1 | E31: 2025Q2 | F31: 2025Q3 | G31: 2025Q4
C32: IEA | D32: =D24-'202502'!D24 -> -0.2 | E32: =E24-'202502'!E24 -> -0.4 | F32: =F24-'202502'!F24 -> -0.4 | G32: =G24-'202502'!G24 -> 1.4210855e-14
C33: EIA | D33: =D25-'202502'!D25 -> -0.02 | E33: =E25-'202502'!E25 -> 0.21 | F33: =F25-'202502'!F25 -> 0.23 | G33: =G25-'202502'!G25 -> 0.26
C34: S&P | D34: =D26-'202502'!D26 -> -0.49577282 | E34: =E26-'202502'!E26 -> -0.28133541 | F34: =F26-'202502'!F26 -> -0.6816079 | G34: =G26-'202502'!G26 -> -0.48050121
C35: WM | D35: =D27-'202502'!D27 -> -0.22 | E35: =E27-'202502'!E27 -> -0.04 | F35: =F27-'202502'!F27 -> 0.02 | G35: =G27-'202502'!G27 -> -0.02
C36: Rystad | D36: =D28-'202502'!D28 -> -0.15 | E36: =E28-'202502'!E28 -> -0.19 | F36: =F28-'202502'!F28 -> -0.51 | G36: =G28-'202502'!G28 -> -0.02

Sheet 202504
D2: 2025Q1 | E2: 2025Q2 | F2: 2025Q3 | G2: 2025Q4
C3: 供应 | D3: 103.3 | E3: 104.2 | F3: 104.9 | G3: 105.5
B4: IEA | C4: 需求 | D4: 102.5 | E4: 103.8 | F4: 104.9 | G4: 104.4
C5: 供需差 | D5: =D3-D4 -> 0.8 | E5: =E3-E4 -> 0.4 | F5: =F3-F4 -> 0 | G5: =G3-G4 -> 1.1
B7: EIA | C7: 供应 | D7: 103.4 | E7: 103.68 | F7: 104.49 | G7: 105.59
C8: 需求 | D8: 103.89 | E8: 103.74 | F8: 104.47 | G8: 104.44
C9: 供需差 | D9: =D7-D8 -> -0.49 | E9: =E7-E8 -> -0.06 | F9: =F7-F8 -> 0.02 | G9: =G7-G8 -> 1.15
C11: 供应 | D11: 105 | E11: 105.7 | F11: 106 | G11: 106.5
B12: S&P | C12: 需求 | D12: 104.3 | E12: 105.6 | F12: 107.4 | G12: 107.2
C13: 供需差 | D13: =D11-D12 -> 0.7 | E13: =E11-E12 -> 0.1 | F13: =F11-F12 -> -1.4 | G13: =G11-G12 -> -0.7
C15: 供应 | D15: 103.64 | E15: 104.33 | F15: 105.12 | G15: 106.4
B16: WM | C16: 需求 | D16: 103.24 | E16: 104.05 | F16: 105.86 | G16: 105.7
C17: 供需差 | D17: =D15-D16 -> 0.4 | E17: =E15-E16 -> 0.28 | F17: =F15-F16 -> -0.74 | G17: =G15-G16 -> 0.7
B19: Rystad | C19: 供应 | D19: 102.85 | E19: 103.61 | F19: 105.1 | G19: 106.07
C20: 需求 | D20: 103.88 | E20: 103.71 | F20: 105.35 | G20: 105.3
C21: 供需差 | D21: =D19-D20 -> -1.03 | E21: =E19-E20 -> -0.1 | F21: =F19-F20 -> -0.25 | G21: =G19-G20 -> 0.77
D23: 2025Q1 | E23: 2025Q2 | F23: 2025Q3 | G23: 2025Q4
C24: IEA | D24: =D5 -> 0.8 | E24: =E5 -> 0.4 | F24: =F5 -> 0 | G24: =G5 -> 1.1
C25: EIA | D25: =D9 -> -0.49 | E25: =E9 -> -0.06 | F25: =F9 -> 0.02 | G25: =G9 -> 1.15
C26: S&P | D26: =D13 -> 0.7 | E26: =E13 -> 0.1 | F26: =F13 -> -1.4 | G26: =G13 -> -0.7
C27: WM | D27: =D17 -> 0.4 | E27: =E17 -> 0.28 | F27: =F17 -> -0.74 | G27: =G17 -> 0.7
C28: Rystad | D28: =D21 -> -1.03 | E28: =E21 -> -0.1 | F28: =F21 -> -0.25 | G28: =G21 -> 0.77
B31: 与上一月的变化 | D31: 2025Q1 | E31: 2025Q2 | F31: 2025Q3 | G31: 2025Q4
C32: IEA | D32: =D24-'202503'!D24 -> 0.4 | E32: =E24-'202503'!E24 -> -0.1 | F32: =F24-'202503'!F24 -> -0.1 | G32: =G24-'202503'!G24 -> 0.2
C33: EIA | D33: =D25-'202503'!D25 -> 0.08 | E33: =E25-'202503'!E25 -> -0.53 | F33: =F25-'202503'!F25 -> -0.65 | G33: =G25-'202503'!G25 -> 0.06
C34: S&P | D34: =D26-'202503'!D26 -> 0.4 | E34: =E26-'202503'!E26 -> 0.1 | F34: =F26-'202503'!F26 -> 0.3 | G34: =G26-'202503'!G26 -> 0.1
C35: WM | D35: =D27-'202503'!D27 -> -0.45 | E35: =E27-'202503'!E27 -> -0.13 | F35: =F27-'202503'!F27 -> -0.21 | G35: =G27-'202503'!G27 -> -0.3
C36: Rystad | D36: =D28-'202503'!D28 -> -0.22 | E36: =E28-'202503'!E28 -> -0.48 | F36: =F28-'202503'!F28 -> -0.68 | G36: =G28-'202503'!G28 -> -1.04

Sheet 202505
D2: 2025Q1 | E2: 2025Q2 | F2: 2025Q3 | G2: 2025Q4
C3: 供应 | D3: 103.1 | E3: 104 | F3: 104.7 | G3: 105.1
B4: IEA | C4: 需求 | D4: 102.4 | E4: 103.2 | F4: 104.5 | G4: 104
C5: 供需差 | D5: =D3-D4 -> 0.7 | E5: =E3-E4 -> 0.8 | F5: =F3-F4 -> 0.2 | G5: =G3-G4 -> 1.1
B7: EIA | C7: 供应 | D7: 103.34 | E7: 103.73 | F7: 104.46 | G7: 104.87
C8: 需求 | D8: 103.53 | E8: 103.17 | F8: 103.78 | G8: 104.09
C9: 供需差 | D9: =D7-D8 -> -0.19 | E9: =E7-E8 -> 0.56 | F9: =F7-F8 -> 0.68 | G9: =G7-G8 -> 0.78
C11: 供应 | D11: 105.04 | E11: 106.13 | F11: 105.98 | G11: 106.42
B12: S&P | C12: 需求 | D12: 104.27 | E12: 104.86 | F12: 106.51 | G12: 106.38
C13: 供需差 | D13: =D11-D12 -> 0.77 | E13: =E11-E12 -> 1.27 | F13: =F11-F12 -> -0.53 | G13: =G11-G12 -> 0.04
C15: 供应 | D15: 103.47 | E15: 104.24 | F15: 104.85 | G15: 106.08
B16: WM | C16: 需求 | D16: 103.18 | E16: 104.23 | F16: 105.84 | G16: 105.73
C17: 供需差 | D17: =D15-D16 -> 0.29 | E17: =E15-E16 -> 0.01 | F17: =F15-F16 -> -0.99 | G17: =G15-G16 -> 0.35
B19: Rystad | C19: 供应 | D19: 102.86 | E19: 103.78 | F19: 104.75 | G19: 105.47
C20: 需求 | D20: 103.82 | E20: 103.59 | F20: 105.23 | G20: 105.16
C21: 供需差 | D21: =D19-D20 -> -0.96 | E21: =E19-E20 -> 0.19 | F21: =F19-F20 -> -0.48 | G21: =G19-G20 -> 0.31
D23: 2025Q1 | E23: 2025Q2 | F23: 2025Q3 | G23: 2025Q4
C24: IEA | D24: =D5 -> 0.7 | E24: =E5 -> 0.8 | F24: =F5 -> 0.2 | G24: =G5 -> 1.1
C25: EIA | D25: =D9 -> -0.19 | E25: =E9 -> 0.56 | F25: =F9 -> 0.68 | G25: =G9 -> 0.78
C26: S&P | D26: =D13 -> 0.77 | E26: =E13 -> 1.27 | F26: =F13 -> -0.53 | G26: =G13 -> 0.04
C27: WM | D27: =D17 -> 0.29 | E27: =E17 -> 0.01 | F27: =F17 -> -0.99 | G27: =G17 -> 0.35
C28: Rystad | D28: =D21 -> -0.96 | E28: =E21 -> 0.19 | F28: =F21 -> -0.48 | G28: =G21 -> 0.31
B31: 与上一月的变化 | D31: 2025Q1 | E31: 2025Q2 | F31: 2025Q3 | G31: 2025Q4
C32: IEA | D32: =D24-'202504'!D24 -> -0.1 | E32: =E24-'202504'!E24 -> 0.4 | F32: =F24-'202504'!F24 -> 0.2 | G32: =G24-'202504'!G24 -> 0
C33: EIA | D33: =D25-'202504'!D25 -> 0.3 | E33: =E25-'202504'!E25 -> 0.62 | F33: =F25-'202504'!F25 -> 0.66 | G33: =G25-'202504'!G25 -> -0.37
C34: S&P | D34: =D26-'202504'!D26 -> 0.07 | E34: =E26-'202504'!E26 -> 1.17 | F34: =F26-'202504'!F26 -> 0.87 | G34: =G26-'202504'!G26 -> 0.74
C35: WM | D35: =D27-'202504'!D27 -> -0.11 | E35: =E27-'202504'!E27 -> -0.27 | F35: =F27-'202504'!F27 -> -0.25 | G35: =G27-'202504'!G27 -> -0.35
C36: Rystad | D36: =D28-'202504'!D28 -> 0.07 | E36: =E28-'202504'!E28 -> 0.29 | F36: =F28-'202504'!F28 -> -0.23 | G36: =G28-'202504'!G28 -> -0.46

Sheet 202506
D2: 2025Q1 | E2: 2025Q2 | F2: 2025Q3 | G2: 2025Q4 | H2: 2026Q1
C3: 供应 | D3: 103.42 | E3: 104.5 | F3: 105.11 | G3: 105.44 | H3: 105.17
B4: IEA | C4: 需求 | D4: 102.5 | E4: 103.9 | F4: 104.9 | G4: 104.3 | H4: 103.2
C5: 供需差 | D5: =D3-D4 -> 0.92 | E5: =E3-E4 -> 0.6 | F5: =F3-F4 -> 0.21 | G5: =G3-G4 -> 1.14 | H5: =H3-H4 -> 1.97
B7: EIA | C7: 供应 | D7: 103.19 | E7: 103.81 | F7: 104.42 | G7: 105.07 | H7: 104.79
C8: 需求 | D8: 103.22 | E8: 103.33 | F8: 104.01 | G8: 104.32 | H8: 104.18
C9: 供需差 | D9: =D7-D8 -> -0.03 | E9: =E7-E8 -> 0.48 | F9: =F7-F8 -> 0.41 | G9: =G7-G8 -> 0.75 | H9: =H7-H8 -> 0.61
C11: 供应 | D11: 104.94628 | E11: 106.07082 | F11: 106.7303 | G11: 107.7478 | H11: 106.52
B12: S&P | C12: 需求 | D12: 104.06679 | E12: 104.93137 | F12: 106.57849 | G12: 106.38369 | H12: 104.73
C13: 供需差 | D13: =D11-D12 -> 0.87949379 | E13: =E11-E12 -> 1.139449 | F13: =F11-F12 -> 0.15180722 | G13: =G11-G12 -> 1.3641152 | H13: =H11-H12 -> 1.79
C15: 供应 | D15: 103.4 | E15: 104.1 | F15: 104.97 | G15: 105.7 | H15: 106.1
B16: WM | C16: 需求 | D16: 103.02 | E16: 103.73 | F16: 105.43 | G16: 105.33 | H16: 103.59
C17: 供需差 | D17: =D15-D16 -> 0.38 | E17: =E15-E16 -> 0.37 | F17: =F15-F16 -> -0.46 | G17: =G15-G16 -> 0.37 | H17: =H15-H16 -> 2.51
B19: Rystad | C19: 供应 | D19: 102.76 | E19: 103.83 | F19: 105 | G19: 105.59 | H19: 105.27
C20: 需求 | D20: 103.43 | E20: 103.85 | F20: 104.89 | G20: 104.82 | H20: 103.97
C21: 供需差 | D21: =D19-D20 -> -0.67 | E21: =E19-E20 -> -0.02 | F21: =F19-F20 -> 0.11 | G21: =G19-G20 -> 0.77 | H21: =H19-H20 -> 1.3
D23: 2025Q1 | E23: 2025Q2 | F23: 2025Q3 | G23: 2025Q4 | H23: 2026Q1
C24: IEA | D24: =D5 -> 0.92 | E24: =E5 -> 0.6 | F24: =F5 -> 0.21 | G24: =G5 -> 1.14 | H24: =H5 -> 1.97
C25: EIA | D25: =D9 -> -0.03 | E25: =E9 -> 0.48 | F25: =F9 -> 0.41 | G25: =G9 -> 0.75 | H25: =H9 -> 0.61
C26: S&P | D26: =D13 -> 0.87949379 | E26: =E13 -> 1.139449 | F26: =F13 -> 0.15180722 | G26: =G13 -> 1.3641152 | H26: =H13 -> 1.79
C27: WM | D27: =D17 -> 0.38 | E27: =E17 -> 0.37 | F27: =F17 -> -0.46 | G27: =G17 -> 0.37 | H27: =H17 -> 2.51
C28: Rystad | D28: =D21 -> -0.67 | E28: =E21 -> -0.02 | F28: =F21 -> 0.11 | G28: =G21 -> 0.77 | H28: =H21 -> 1.3
B31: 与上一月的变化 | D31: 2025Q1 | E31: 2025Q2 | F31: 2025Q3 | G31: 2025Q4 | H31: 2026Q1
C32: IEA | D32: =D24-'202505'!D24 -> 0.22 | E32: =E24-'202505'!E24 -> -0.2 | F32: =F24-'202505'!F24 -> 0.01 | G32: =G24-'202505'!G24 -> 0.04
C33: EIA | D33: =D25-'202505'!D25 -> 0.16 | E33: =E25-'202505'!E25 -> -0.08 | F33: =F25-'202505'!F25 -> -0.27 | G33: =G25-'202505'!G25 -> -0.03
C34: S&P | D34: =D26-'202505'!D26 -> 0.10949379 | E34: =E26-'202505'!E26 -> -0.13055102 | F34: =F26-'202505'!F26 -> 0.68180722 | G34: =G26-'202505'!G26 -> 1.3241152
C35: WM | D35: =D27-'202505'!D27 -> 0.09 | E35: =E27-'202505'!E27 -> 0.36 | F35: =F27-'202505'!F27 -> 0.53 | G35: =G27-'202505'!G27 -> 0.02
C36: Rystad | D36: =D28-'202505'!D28 -> 0.29 | E36: =E28-'202505'!E28 -> -0.21 | F36: =F28-'202505'!F28 -> 0.59 | G36: =G28-'202505'!G28 -> 0.46

Sheet 202507
D2: 2025Q1 | E2: 2025Q2 | F2: 2025Q3 | G2: 2025Q4 | H2: 2026Q1
C3: 供应 | D3: 103.4 | E3: 104.5 | F3: 105.1 | G3: 105.4 | H3: 105.2
B4: IEA | C4: 需求 | D4: 102.4 | E4: 103.6 | F4: 104.8 | G4: 104.3 | H4: 103.1
C5: 供需差 | D5: =D3-D4 -> 1 | E5: =E3-E4 -> 0.9 | F5: =F3-F4 -> 0.3 | G5: =G3-G4 -> 1.1 | H5: =H3-H4 -> 2.1
B7: EIA | C7: 供应 | D7: 103.3206 | E7: 104.26809 | F7: 104.739 | G7: 105.04901 | H7: 104.59159
C8: 需求 | D8: 102.16181 | E8: 103.13489 | F8: 104.38079 | G8: 104.43451 | H8: 103.3684
C9: 供需差 | D9: =D7-D8 -> 1.1587885 | E9: =E7-E8 -> 1.1332002 | F9: =F7-F8 -> 0.35821304 | G9: =G7-G8 -> 0.61450134 | H9: =H7-H8 -> 1.223191
C11: 供应 | D11: 104.94422 | E11: 106.49457 | F11: 107.44536 | G11: 108.58896 | H11: 108.35312 | S11: 102.908 | T11: 103.44285
B12: S&P | C12: 需求 | D12: 103.94121 | E12: 105.0292 | F12: 107.26843 | G12: 106.84737 | H12: 104.91686 | S12: 103.837 | T12: 103.90995
C13: 供需差 | D13: =D11-D12 -> 1.0030144 | E13: =E11-E12 -> 1.4653706 | F13: =F11-F12 -> 0.17692975 | G13: =G11-G12 -> 1.7415899 | H13: =H11-H12 -> 3.4362635 | S13: 105.754 | T13: 105.36018
S14: 105.227 | T14: 106.64365
C15: 供应 | D15: 103.44 | E15: 103.91 | F15: 105.36 | G15: 106.64 | H15: 106.81 | S15: 103.487 | T15: 106.81129
B16: WM | C16: 需求 | D16: 102.91 | E16: 103.84 | F16: 105.75 | G16: 105.23 | H16: 103.49
C17: 供需差 | D17: =D15-D16 -> 0.53 | E17: =E15-E16 -> 0.07 | F17: =F15-F16 -> -0.39 | G17: =G15-G16 -> 1.41 | H17: =H15-H16 -> 3.32
B19: Rystad | C19: 供应 | D19: 102.74 | E19: 103.25 | F19: 105.24 | G19: 106.24 | H19: 105.84
C20: 需求 | D20: 103.06 | E20: 103.97 | F20: 105.32 | G20: 104.84 | H20: 104.47
C21: 供需差 | D21: =D19-D20 -> -0.32 | E21: =E19-E20 -> -0.72 | F21: =F19-F20 -> -0.08 | G21: =G19-G20 -> 1.4 | H21: =H19-H20 -> 1.37
D23: 2025Q1 | E23: 2025Q2 | F23: 2025Q3 | G23: 2025Q4 | H23: 2026Q1
C24: IEA | D24: =D5 -> 1 | E24: =E5 -> 0.9 | F24: =F5 -> 0.3 | G24: =G5 -> 1.1 | H24: =H5 -> 2.1
C25: EIA | D25: =D9 -> 1.1587885 | E25: =E9 -> 1.1332002 | F25: =F9 -> 0.35821304 | G25: =G9 -> 0.61450134 | H25: =H9 -> 1.223191
C26: S&P | D26: =D13 -> 1.0030144 | E26: =E13 -> 1.4653706 | F26: =F13 -> 0.17692975 | G26: =G13 -> 1.7415899 | H26: =H13 -> 3.4362635
C27: WM | D27: =D17 -> 0.53 | E27: =E17 -> 0.07 | F27: =F17 -> -0.39 | G27: =G17 -> 1.41 | H27: =H17 -> 3.32
C28: Rystad | D28: =D21 -> -0.32 | E28: =E21 -> -0.72 | F28: =F21 -> -0.08 | G28: =G21 -> 1.4 | H28: =H21 -> 1.37
B31: 与上一月的变化 | D31: 2025Q1 | E31: 2025Q2 | F31: 2025Q3 | G31: 2025Q4 | H31: 2026Q1
C32: IEA | D32: =D24-'202506'!D24 -> 0.08 | E32: =E24-'202506'!E24 -> 0.3 | F32: =F24-'202506'!F24 -> 0.09 | G32: =G24-'202506'!G24 -> -0.04
C33: EIA | D33: =D25-'202506'!D25 -> 1.1887885 | E33: =E25-'202506'!E25 -> 0.65320023 | F33: =F25-'202506'!F25 -> -0.05178696 | G33: =G25-'202506'!G25 -> -0.13549866
C34: S&P | D34: =D26-'202506'!D26 -> 0.12352061 | E34: =E26-'202506'!E26 -> 0.32592167 | F34: =F26-'202506'!F26 -> 0.025122527 | G34: =G26-'202506'!G26 -> 0.37747471
C35: WM | D35: =D27-'202506'!D27 -> 0.15 | E35: =E27-'202506'!E27 -> -0.3 | F35: =F27-'202506'!F27 -> 0.07 | G35: =G27-'202506'!G27 -> 1.04
C36: Rystad | D36: =D28-'202506'!D28 -> 0.35 | E36: =E28-'202506'!E28 -> -0.7 | F36: =F28-'202506'!F28 -> -0.19 | G36: =G28-'202506'!G28 -> 0.63

Sheet 202508
D2: 2025Q1 | E2: 2025Q2 | F2: 2025Q3 | G2: 2025Q4 | H2: 2026Q1
C3: 供应 | D3: 103.5 | E3: 105 | F3: 105.7 | G3: 106.3 | H3: 106.1
B4: IEA | C4: 需求 | D4: 102.4 | E4: 103.4 | F4: 104.7 | G4: 104.2 | H4: 102.9
C5: 供需差 | D5: =D3-D4 -> 1.1 | E5: =E3-E4 -> 1.6 | F5: =F3-F4 -> 1 | G5: =G3-G4 -> 2.1 | H5: =H3-H4 -> 3.2
B7: EIA | C7: 供应 | D7: 103.36021 | E7: 104.45929 | F7: 105.08019 | G7: 105.50615 | H7: 105.15304
C8: 需求 | D8: 102.16181 | E8: 103.13489 | F8: 104.38079 | G8: 104.43451 | H8: 103.38961
C9: 供需差 | D9: =D7-D8 -> 1.1983994 | E9: =E7-E8 -> 1.3243998 | F9: =F7-F8 -> 0.69939867 | G9: =G7-G8 -> 1.0716447 | H9: =H7-H8 -> 1.7634353
C11: 供应 | D11: 104.85318 | E11: 106.40185 | F11: 107.41757 | G11: 108.36847 | H11: 108.32879
B12: S&P | C12: 需求 | D12: 104.15909 | E12: 104.87377 | F12: 106.72935 | G12: 106.51629 | H12: 104.79482
C13: 供需差 | D13: =D11-D12 -> 0.69409534 | E13: =E11-E12 -> 1.5280756 | F13: =F11-F12 -> 0.68822387 | G13: =G11-G12 -> 1.8521761 | H13: =H11-H12 -> 3.5339702
C15: 供应 | D15: 103.40598 | E15: 103.76894 | F15: 105.31895 | G15: 106.61452 | H15: 106.96316
B16: WM | C16: 需求 | D16: 102.778 | E16: 103.605 | F16: 105.77 | G16: 105.306 | H16: 103.57
C17: 供需差 | D17: =D15-D16 -> 0.62797897 | E17: =E15-E16 -> 0.1639399 | F17: =F15-F16 -> -0.45105408 | G17: =G15-G16 -> 1.3085203 | H17: =H15-H16 -> 3.393161
B19: Rystad | C19: 供应 | D19: 102.53313 | E19: 103.53423 | F19: 105.491 | G19: 106.51193 | H19: 106.16713
C20: 需求 | D20: 103.02433 | E20: 104.03267 | F20: 105.80733 | G20: 105.58367 | H20: 104.791
C21: 供需差 | D21: =D19-D20 -> -0.4912 | E21: =E19-E20 -> -0.49843333 | F21: =F19-F20 -> -0.31633333 | G21: =G19-G20 -> 0.92826667 | H21: =H19-H20 -> 1.3761333
D23: 2025Q1 | E23: 2025Q2 | F23: 2025Q3 | G23: 2025Q4 | H23: 2026Q1
C24: IEA | D24: =D5 -> 1.1 | E24: =E5 -> 1.6 | F24: =F5 -> 1 | G24: =G5 -> 2.1 | H24: =H5 -> 3.2
C25: EIA | D25: =D9 -> 1.1983994 | E25: =E9 -> 1.3243998 | F25: =F9 -> 0.69939867 | G25: =G9 -> 1.0716447 | H25: =H9 -> 1.7634353
C26: S&P | D26: =D13 -> 0.69409534 | E26: =E13 -> 1.5280756 | F26: =F13 -> 0.68822387 | G26: =G13 -> 1.8521761 | H26: =H13 -> 3.5339702
C27: WM | D27: =D17 -> 0.62797897 | E27: =E17 -> 0.1639399 | F27: =F17 -> -0.45105408 | G27: =G17 -> 1.3085203 | H27: =H17 -> 3.393161
C28: Rystad | D28: =D21 -> -0.4912 | E28: =E21 -> -0.49843333 | F28: =F21 -> -0.31633333 | G28: =G21 -> 0.92826667 | H28: =H21 -> 1.3761333
B31: 与上一月的变化 | D31: 2025Q1 | E31: 2025Q2 | F31: 2025Q3 | G31: 2025Q4 | H31: 2026Q1
C32: IEA | D32: =D24-'202507'!D24 -> 0.1 | E32: =E24-'202507'!E24 -> 0.7 | F32: =F24-'202507'!F24 -> 0.7 | G32: =G24-'202507'!G24 -> 1
C33: EIA | D33: =D25-'202507'!D25 -> 0.039610903 | E33: =E25-'202507'!E25 -> 0.19119954 | F33: =F25-'202507'!F25 -> 0.34118563 | G33: =G25-'202507'!G25 -> 0.45714339
C34: S&P | D34: =D26-'202507'!D26 -> -0.30891906 | E34: =E26-'202507'!E26 -> 0.06270495 | F34: =F26-'202507'!F26 -> 0.51129412 | G34: =G26-'202507'!G26 -> 0.11058625
C35: WM | D35: =D27-'202507'!D27 -> 0.097978975 | E35: =E27-'202507'!E27 -> 0.093939897 | F35: =F27-'202507'!F27 -> -0.061054081 | G35: =G27-'202507'!G27 -> -0.10147967
C36: Rystad | D36: =D28-'202507'!D28 -> -0.1712 | E36: =E28-'202507'!E28 -> 0.22156667 | F36: =F28-'202507'!F28 -> -0.23633333 | G36: =G28-'202507'!G28 -> -0.47173333

Sheet 202509
D2: 2025Q1 | E2: 2025Q2 | F2: 2025Q3 | G2: 2025Q4 | H2: 2026Q1
C3: 供应 | D3: 103.5 | E3: 105 | F3: 106.2 | G3: 107.3 | H3: 107.1
B4: IEA | C4: 需求 | D4: 102.5 | E4: 103.6 | F4: 104.6 | G4: 104.2 | H4: 103
C5: 供需差 | D5: =D3-D4 -> 1 | E5: =E3-E4 -> 1.4 | F5: =F3-F4 -> 1.6 | G5: =G3-G4 -> 3.1 | H5: =H3-H4 -> 4.1
B7: EIA | C7: 供应 | D7: 103.59 | E7: 105.06 | F7: 106.11 | G7: 106.63 | H7: 105.77
C8: 需求 | D8: 102.16181 | E8: 103.71 | F8: 104.49 | G8: 104.53 | H8: 103.51
C9: 供需差 | D9: =D7-D8 -> 1.4281926 | E9: =E7-E8 -> 1.35 | F9: =F7-F8 -> 1.62 | G9: =G7-G8 -> 2.1 | H9: =H7-H8 -> 2.26
C11: 供应 | D11: 104.87261 | E11: 106.14297 | F11: 107.21263 | G11: 108.35238 | H11: 108.04484
B12: S&P | C12: 需求 | D12: 104.33929 | E12: 105.19018 | F12: 106.73823 | G12: 106.19293 | H12: 104.79018
C13: 供需差 | D13: =D11-D12 -> 0.53331882 | E13: =E11-E12 -> 0.95278041 | F13: =F11-F12 -> 0.47439258 | G13: =G11-G12 -> 2.1594483 | H13: =H11-H12 -> 3.2546619
C15: 供应 | D15: 103.32 | E15: 103.75 | F15: 105.3 | G15: 106.64 | H15: 106.94
B16: WM | C16: 需求 | D16: 103.02 | E16: 103.38 | F16: 105.66 | G16: 105.42 | H16: 103.54
C17: 供需差 | D17: =D15-D16 -> 0.3 | E17: =E15-E16 -> 0.37 | F17: =F15-F16 -> -0.36 | G17: =G15-G16 -> 1.22 | H17: =H15-H16 -> 3.4
B19: Rystad | C19: 供应 | D19: 102.72013 | E19: 103.73187 | F19: 105.8511 | G19: 107.3693 | H19: 106.89403
C20: 需求 | D20: 102.87627 | E20: 103.93123 | F20: 106.17233 | G20: 105.75363 | H20: 104.7716
C21: 供需差 | D21: =D19-D20 -> -0.15613333 | E21: =E19-E20 -> -0.19936667 | F21: =F19-F20 -> -0.32123333 | G21: =G19-G20 -> 1.6156667 | H21: =H19-H20 -> 2.1224333
D23: 2025Q1 | E23: 2025Q2 | F23: 2025Q3 | G23: 2025Q4 | H23: 2026Q1
C24: IEA | D24: =D5 -> 1 | E24: =E5 -> 1.4 | F24: =F5 -> 1.6 | G24: =G5 -> 3.1 | H24: =H5 -> 4.1
C25: EIA | D25: =D9 -> 1.4281926 | E25: =E9 -> 1.35 | F25: =F9 -> 1.62 | G25: =G9 -> 2.1 | H25: =H9 -> 2.26
C26: S&P | D26: =D13 -> 0.53331882 | E26: =E13 -> 0.95278041 | F26: =F13 -> 0.47439258 | G26: =G13 -> 2.1594483 | H26: =H13 -> 3.2546619
C27: WM | D27: =D17 -> 0.3 | E27: =E17 -> 0.37 | F27: =F17 -> -0.36 | G27: =G17 -> 1.22 | H27: =H17 -> 3.4
C28: Rystad | D28: =D21 -> -0.15613333 | E28: =E21 -> -0.19936667 | F28: =F21 -> -0.32123333 | G28: =G21 -> 1.6156667 | H28: =H21 -> 2.1224333
B31: 与上一月的变化 | D31: 2025Q1 | E31: 2025Q2 | F31: 2025Q3 | G31: 2025Q4 | H31: 2026Q1
C32: IEA | D32: =D24-'202508'!D24 -> -0.1 | E32: =E24-'202508'!E24 -> -0.2 | F32: =F24-'202508'!F24 -> 0.6 | G32: =G24-'202508'!G24 -> 1
C33: EIA | D33: =D25-'202508'!D25 -> 0.22979324 | E33: =E25-'202508'!E25 -> 0.02560023 | F33: =F25-'202508'!F25 -> 0.92060133 | G33: =G25-'202508'!G25 -> 1.0283553
C34: S&P | D34: =D26-'202508'!D26 -> -0.16077653 | E34: =E26-'202508'!E26 -> -0.57529518 | F34: =F26-'202508'!F26 -> -0.21383129 | G34: =G26-'202508'!G26 -> 0.30727218
C35: WM | D35: =D27-'202508'!D27 -> -0.32797897 | E35: =E27-'202508'!E27 -> 0.2060601 | F35: =F27-'202508'!F27 -> 0.091054081 | G35: =G27-'202508'!G27 -> -0.088520334
C36: Rystad | D36: =D28-'202508'!D28 -> 0.33506667 | E36: =E28-'202508'!E28 -> 0.29906667 | F36: =F28-'202508'!F28 -> -0.0049 | G36: =G28-'202508'!G28 -> 0.6874

Sheet 202510
D2: 2025Q1 | E2: 2025Q2 | F2: 2025Q3 | G2: 2025Q4 | H2: 2026Q1
C3: 供应 | D3: 103.5 | E3: 105.3 | F3: 106.9 | G3: 107.6 | H3: 107.4
B4: IEA | C4: 需求 | D4: 102.5 | E4: 103.4 | F4: 105 | G4: 104.5 | H4: 103.1
C5: 供需差 | D5: =D3-D4 -> 1 | E5: =E3-E4 -> 1.9 | F5: =F3-F4 -> 1.9 | G5: =G3-G4 -> 3.1 | H5: =H3-H4 -> 4.3
B7: EIA | C7: 供应 | D7: 103.61 | E7: 105.03 | F7: 106.62 | G7: 106.85 | H7: 106.07
C8: 需求 | D8: 102.21 | E8: 103.77 | F8: 104.61 | G8: 104.64 | H8: 103.66
C9: 供需差 | D9: =D7-D8 -> 1.4 | E9: =E7-E8 -> 1.26 | F9: =F7-F8 -> 2.01 | G9: =G7-G8 -> 2.21 | H9: =H7-H8 -> 2.41
C11: 供应 | D11: 104.87261 | E11: 106.14297 | F11: 107.21263 | G11: 108.35238 | H11: 108.04484
B12: S&P | C12: 需求 | D12: 104.33929 | E12: 105.19018 | F12: 106.73823 | G12: 106.19293 | H12: 104.79018
C13: 供需差 | D13: =D11-D12 -> 0.53331882 | E13: =E11-E12 -> 0.95278041 | F13: =F11-F12 -> 0.47439258 | G13: =G11-G12 -> 2.1594483 | H13: =H11-H12 -> 3.2546619
